Workbook

Sheet 2026年19周纯洗箱情况
A1: 经营单位 | B1: 网点 | C1: 纯洗箱量 | D1: 纯洗箱费 | E1: 合计修洗量 | F1: 合计修洗费 | G1: 修洗箱单箱 | H1: 修箱单箱 | I1: 单箱差额
A2: 南岗分公司 | B2: 南岗堆场 | C2: 1 | D2: 63.02 | E2: 100 | F2: 23763.26 | G2: 237.63 | H2: 239.4 | I2: 1.76
A3: 南岗分公司 | B3: 东江仓码头 | C3: 1 | D3: 63.02 | E3: 90 | F3: 9616.25 | G3: 106.85 | H3: 107.34 | I3: 0.49
A4: 深圳运营中心 | B4: 深圳大铲湾 | C4: 0 | D4: 0 | E4: 102 | F4: 34681.21 | G4: 340.01 | H4: 340.01 | I4: 0
A5: 华慧良修 | B5: 深圳蛇口堆场 | C5: 4 | D5: 118.24 | E5: 321 | F5: 86997.92 | G5: 271.02 | H5: 274.07 | I5: 3.05
A6: 深圳运营中心 | B6: 汕头广澳 | C6: 0 | D6: 0 | E6: 0 | F6: 0 | G6: #DIV/0! | H6: #DIV/0! | I6: #DIV/0!
A7: 深圳运营中心 | B7: 汕头堆场 | C7: 0 | D7: 0 | E7: 242 | F7: 59793.31 | G7: 247.08 | H7: 247.08 | I7: 0
A8: 深圳运营中心 | B8: 汕头国集 | C8: 0 | D8: 0 | E8: 0 | F8: 0 | G8: #DIV/0! | H8: #DIV/0! | I8: #DIV/0!
A9: 广州运营中心 | B9: 黄埔旧港 | C9: 653 | D9: 34360.5 | E9: 1128 | F9: 122134.95 | G9: 108.28 | H9: 184.79 | I9: 76.51
A10: 广州运营中心 | B10: 淡水河码头 | C10: 0 | D10: 0 | E10: 0 | F10: 0 | G10: #DIV/0! | H10: #DIV/0! | I10: #DIV/0!
A11: 广州运营中心 | B11: 新沙港 | C11: 0 | D11: 0 | E11: 9 | F11: 2368.5 | G11: 263.17 | H11: 263.17 | I11: 0
A12: 广州运营中心 | B12: 南沙三期自营 | C12: 0 | D12: 0 | E12: 0 | F12: 0 | G12: #DIV/0! | H12: #DIV/0! | I12: #DIV/0!
A13: 广州运营中心 | B13: 南沙一期码头 | C13: 10 | D13: 630.2 | E13: 135 | F13: 25806.78 | G13: 191.16 | H13: 201.41 | I13: 10.25
A14: 广州运营中心 | B14: 南沙二期 | C14: 6 | D14: 87.6 | E14: 191 | F14: 46614.68 | G14: 244.06 | H14: 251.5 | I14: 7.44
A15: 广州运营中心 | B15: 虎门二期码头 | C15: 266 | D15: 12068.33 | E15: 325 | F15: 35469.28 | G15: 109.14 | H15: 396.63 | I15: 287.49
A16: 广州运营中心 | B16: 虎门港一期 | C16: 0 | D16: 0 | E16: 0 | F16: 0 | G16: #DIV/0! | H16: #DIV/0! | I16: #DIV/0!
A17: 广州运营中心 | B17: 虎门三期码头 | C17: 42 | D17: 1543.99 | E17: 42 | F17: 1543.99 | G17: 36.76 | H17: #DIV/0! | I17: #DIV/0!
A18: 广州运营中心 | B18: 惠州龙溪 | C18: 170 | D18: 8129.58 | E18: 309 | F18: 38544.59 | G18: 124.74 | H18: 218.81 | I18: 94.07
A19: 珠三角运营中心 | B19: 佛山南庄 | C19: 83 | D19: 2678.35 | E19: 232 | F19: 43449.76 | G19: 187.28 | H19: 273.63 | I19: 86.35
A20: 珠三角运营中心 | B20: 白坭南拓 | C20: 0 | D20: 0 | E20: 57 | F20: 12095.76 | G20: 212.21 | H20: 212.21 | I20: 0
A21: 珠三角运营中心 | B21: 佛山南鲲 | C21: 1 | D21: 31.51 | E21: 38 | F21: 11310.24 | G21: 297.64 | H21: 304.83 | I21: 7.19
A22: 珠三角运营中心 | B22: 佛山高明外堆场 | C22: 15 | D22: 472.65 | E22: 167 | F22: 40095.1 | G22: 240.09 | H22: 260.67 | I22: 20.58
A23: 珠三角运营中心 | B23: 佛山高明珠江码头 | C23: 0 | D23: 0 | E23: 0 | F23: 0 | G23: #DIV/0! | H23: #DIV/0! | I23: #DIV/0!
A24: 珠三角运营中心 | B24: 佛山高明战备码头 | C24: 1 | D24: 63.02 | E24: 1 | F24: 63.02 | G24: 63.02 | H24: #DIV/0! | I24: #DIV/0!
A25: 珠三角运营中心 | B25: 珠海高栏 | C25: 0 | D25: 0 | E25: 146 | F25: 39195.82 | G25: 268.46 | H25: 268.46 | I25: 0
A26: 珠三角运营中心 | B26: 肇庆南江 | C26: 0 | D26: 0 | E26: 35 | F26: 10601.08 | G26: 302.89 | H26: 302.89 | I26: 0
A27: 珠三角运营中心 | B27: 肇庆新港 | C27: 62 | D27: 2457.78 | E27: 73 | F27: 5521.81 | G27: 75.64 | H27: 278.55 | I27: 202.91
A28: 珠三角运营中心 | B28: 江门外海 | C28: 0 | D28: 0 | E28: 111 | F28: 34468.74 | G28: 310.53 | H28: 310.53 | I28: 0
A29: 珠三角运营中心 | B29: 贵阳陆港铁路场 | C29: 0 | D29: 0 | E29: 0 | F29: 0 | G29: #DIV/0! | H29: #DIV/0! | I29: #DIV/0!
A30: 珠三角运营中心 | B30: 顺德乐从 | C30: 0 | D30: 0 | E30: 286 | F30: 40496.98 | G30: 141.6 | H30: 141.6 | I30: 0
A31: 珠三角运营中心 | B31: 佛山顺乐自营 | C31: 0 | D31: 0 | E31: 279 | F31: 64412.93 | G31: 230.87 | H31: 230.87 | I31: 0
A32: 珠三角运营中心 | B32: 顺德中储粮 | C32: 0 | D32: 0 | E32: 0 | F32: 0 | G32: #DIV/0! | H32: #DIV/0! | I32: #DIV/0!
A33: 珠三角运营中心 | B33: 高明高荷码头 | C33: 45 | D33: 1417.95 | E33: 46 | F33: 1586 | G33: 34.48 | H33: 168.05 | I33: 133.57
A34: 粤西运营中心 | B34: 湛江外堆场 | C34: 193 | D34: 6298.33 | E34: 291 | F34: 79244.29 | G34: 272.32 | H34: 744.35 | I34: 472.03
A35: 粤西运营中心 | B35: 湛江港 | C35: 249 | D35: 14294.09 | E35: 726 | F35: 79699.05 | G35: 109.78 | H35: 137.12 | I35: 27.34
A36: 粤西运营中心 | B36: 水东 | C36: 16 | D36: 819.26 | E36: 117 | F36: 42651.43 | G36: 364.54 | H36: 414.18 | I36: 49.64
A37: 北部湾运营中心 | B37: 防城港外堆场 | C37: 0 | D37: 0 | E37: 477 | F37: 131295.71 | G37: 275.25 | H37: 275.25 | I37: 0
A38: 北部湾运营中心 | B38: 防城港二堆场 | C38: 0 | D38: 0 | E38: 140 | F38: 40343.91 | G38: 288.17 | H38: 288.17 | I38: 0
A39: 北部湾运营中心 | B39: 广西钦州外堆场自营 | C39: 0 | D39: 0 | E39: 896 | F39: 220295.46 | G39: 245.87 | H39: 245.87 | I39: 0
A40: 北部湾运营中心 | B40: 广西钦州港自营 | C40: 0 | D40: 0 | E40: 37 | F40: 12272.21 | G40: 331.68 | H40: 331.68 | I40: 0
...

Sheet 2025年18周
A1: 单位汇总报表 | X1: 自营箱量完成情况
A2: 业务类型 | C2: 中远海干箱 | J2: 第三方干箱 | P2: 其它费用 | T2: 合计 | X2: 生产周期 | Z2: 18
A3: 部门/单位 | C3: 箱量 | D3: 环比 | E3: 产值 | F3: 环比 | G3: 单箱 | H3: 环比 | I3: 移箱费 | J3: 箱量 | K3: 环比 | L3: 产值 | M3: 环比 | N3: 单箱 | O3: 环比 | P3: 冷箱产值 | Q3: 堆场产值 | R3: 其它 | S3: 现金收费 | T3: 箱量 | U3: 产值 | V3: 人均产出 | W3: 人员数量 | X3: 周目标箱量 | Y3: 完成差额 | Z3: 合计目标箱量 | AA3: 合计完成量 | AB3: 合计完成差额
A4: 自营 | B4: 深圳运营中心 | C4: 496 | D4: 104 | E4: 183152.4 | F4: 0.2271 | G4: 369.26 | H4: -0.0302 | I4: 0 | J4: 131 | K4: -36 | L4: 46704 | M4: -0.2028 | N4: 356.52 | O4: 0.0163 | P4: 0 | Q4: 1152068.1 | R4: 6195 | S4: 0 | T4: 627 | U4: 1388119.4 | V4: 33050 | W4: 42 | X4: 900 | Y4: -273 | Z4: 16200 | AA4: 9816 | AB4: -6384
B5: 广州运营中心 | C5: 2849 | D5: -97 | E5: 431050.03 | F5: -0.107 | G5: 151.3 | H5: -0.0766 | I5: 187871.59 | J5: 148 | K5: -54 | L5: 42843 | M5: -0.0504 | N5: 289.48 | O5: 0.2961 | P5: 6218.94 | Q5: 0 | R5: 9540 | T5: 2997 | U5: 677523.56 | V5: 20531 | W5: 33 | X5: 2500 | Y5: 497 | Z5: 45000 | AA5: 49206 | AB5: 4206
B6: 珠三角运营中心 | C6: 2284 | D6: 134 | E6: 519472.11 | F6: 0.0169 | G6: 227.44 | H6: -0.0428 | I6: 119238.58 | J6: 249 | K6: 113 | L6: 82971 | M6: 0.2888 | N6: 333.22 | O6: -0.2961 | P6: 0 | Q6: 9509 | R6: 0 | T6: 2533 | U6: 731190.69 | V6: 12607 | W6: 58 | X6: 3000 | Y6: -467 | Z6: 54000 | AA6: 37125 | AB6: -16875
B7: 粤西运营中心 | C7: 1331 | D7: 358 | E7: 350404.39 | F7: 0.2509 | G7: 263.26 | H7: -0.0856 | I7: 44859.815 | J7: 43 | K7: 21 | L7: 12247 | M7: 1.8 | N7: 284.81 | O7: 0.4325 | P7: 52532.35 | Q7: 13281.6 | R7: 25922.52 | T7: 1374 | U7: 499247.67 | V7: 23774 | W7: 21 | X7: 1100 | Y7: 274 | Z7: 19800 | AA7: 23252 | AB7: 3452
B8: 北部湾运营中心 | C8: 1957 | D8: -203 | E8: 628333.08 | F8: -0.072 | G8: 321.07 | H8: 0.0243 | I8: 495.0306 | J8: 14 | K8: 6 | L8: 2553 | M8: 0.575 | N8: 182.36 | O8: -0.1 | P8: 0 | Q8: 71280.5 | R8: 7290 | T8: 1971 | U8: 709951.61 | V8: 22186 | W8: 32 | X8: 1500 | Y8: 471 | Z8: 27000 | AA8: 37496 | AB8: 10496
B9: 南岗分公司 | C9: 246 | D9: -36 | E9: 41928.99 | F9: -0.0371 | G9: 170.44 | H9: 0.1037 | I9: 10905.057 | J9: 422 | K9: -492 | L9: 50873 | M9: -0.3272 | N9: 120.55 | O9: 0.4571 | P9: 2689.8 | Q9: 82306 | R9: 46144 | S9: 0 | T9: 668 | U9: 234846.85 | V9: 13047 | W9: 18 | X9: 600 | Y9: 68 | Z9: 10800 | AA9: 11177 | AB9: 377
B10: 自营总计 | C10: 9163 | D10: 260 | E10: 2154341 | F10: 0.005 | G10: 235.11 | H10: -0.0235 | I10: 363370.08 | J10: 1007 | K10: -442 | L10: 238191 | M10: -0.046 | N10: 236.54 | O10: 0.3727 | P10: 61441.09 | Q10: 1328445.1 | R10: 95091.52 | S10: 0 | T10: 10170 | U10: 4240879.8 | V10: 20789 | W10: 204 | X10: 9600 | Y10: 570 | Z10: 172800 | AA10: 168072 | AB10: -4728
A11: 合作供应商 | B11: 广州弘运 | C11: 2512 | D11: -189 | E11: 708298.26 | F11: 0.0515 | G11: 281.97 | H11: 0.1306 | I11: 113431.7 | J11: 20 | K11: 10 | L11: 3620 | M11: 0.5159 | N11: 181 | O11: -0.242 | P11: 21766.6 | T11: 2532 | U11: 847116.56
B12: 钦州弘运 | C12: 698 | D12: 189 | E12: 161514.97 | F12: 0.0605 | G12: 231.4 | H12: -0.2266 | I12: 26456.635 | J12: 4 | K12: 4 | L12: 1988 | M12: #DIV/0! | N12: 497 | O12: #DIV/0! | P12: 0 | T12: 702 | U12: 189959.61
B13: 弘运天浩 | C13: 617 | D13: 155 | E13: 133284.5 | F13: 0.5511 | G13: 216.02 | H13: 0.1615 | I13: 38934.998 | J13: 51 | K13: 30 | L13: 13449 | M13: 1.8451 | N13: 263.71 | O13: 0.1715 | P13: 0 | T13: 668 | U13: 185668.5
B14: 万年红 | C14: 340 | D14: 12 | E14: 49228.17 | F14: 0.3322 | G14: 144.79 | H14: 0.2852 | I14: 22759.451 | J14: 0 | K14: 0 | L14: 0 | M14: #DIV/0! | N14: #DIV/0! | O14: #DIV/0! | P14: 0 | T14: 340 | U14: 71987.62
B15: 裕丰 | C15: 326 | D15: -28 | E15: 75398.21 | F15: 0.0982 | G15: 231.28 | H15: 0.1925 | I15: 18490.873 | J15: 0 | K15: 0 | L15: 0 | M15: #DIV/0! | N15: #DIV/0! | O15: #DIV/0! | P15: 0 | T15: 326 | U15: 93889.08
B16: 本港 | C16: 18 | D16: -2 | E16: 3784.37 | F16: -0.6598 | G16: 210.24 | H16: -0.622 | I16: 1030.0444 | J16: 0 | K16: 0 | L16: 0 | M16: #DIV/0! | N16: #DIV/0! | O16: #DIV/0! | P16: 0 | T16: 18 | U16: 4814.41
B17: 坚迅 | C17: 720 | D17: -162 | E17: 195354.31 | F17: -0.1674 | G17: 271.33 | H17: 0.0199 | I17: 50487.291 | J17: 3 | K17: 0 | L17: 581 | M17: 0.1326 | N17: 193.67 | O17: 0.1326 | P17: 0 | T17: 723 | U17: 246422.6
B18: 浚得兴 | C18: 643 | D18: 79 | E18: 180389.36 | F18: 0.2037 | G18: 280.54 | H18: 0.0558 | I18: 38865.716 | J18: 0 | K18: 0 | L18: 0 | M18: #DIV/0! | N18: #DIV/0! | O18: #DIV/0! | P18: 0 | T18: 643 | U18: 219255.08
B19: 深圳天河 | C19: 5 | D19: 1 | E19: 1694.59 | F19: -0.1101 | G19: 338.92 | H19: -0.2881 | I19: 374.975 | J19: 0 | K19: 0 | L19: 0 | M19: #DIV/0! | N19: #DIV/0! | O19: #DIV/0! | P19: 0 | T19: 5 | U19: 2069.57
B20: 信步 | C20: 783 | D20: -65 | E20: 132815.34 | F20: 0.0053 | G20: 169.62 | H20: 0.0888 | I20: 45846.495 | J20: 11 | K20: -8 | L20: 3474 | M20: -0.4784 | N20: 315.82 | O20: -0.099 | P20: 0 | T20: 794 | U20: 182135.83
B21: 万永联 | C21: 161 | D21: -35 | E21: 28371.25 | F21: -0.0313 | G21: 176.22 | H21: 0.1794 | I21: 0 | J21: 0 | K21: 0 | L21: 0 | M21: #DIV/0! | N21: #DIV/0! | O21: #DIV/0! | P21: 0 | T21: 161 | U21: 28371.25
B22: 辉成 | C22: 197 | D22: -54 | E22: 41730.12 | F22: -0.0637 | G22: 211.83 | H22: 0.1929 | I22: 11175.527 | J22: 0 | K22: 0 | L22: 0 | M22: #DIV/0! | N22: #DIV/0! | O22: #DIV/0! | P22: 0 | T22: 197 | U22: 52905.65
B23: 万建达 | C23: 741 | D23: 112 | E23: 277803.3 | F23: 0.2946 | G23: 374.9 | H23: 0.0989 | I23: 0 | J23: 0 | K23: 0 | L23: 0 | M23: #DIV/0! | N23: #DIV/0! | O23: #DIV/0! | P23: 0 | T23: 741 | U23: 277803.3
B24: 别志 | C24: 5 | D24: 5 | E24: 2145.5 | F24: #DIV/0! | G24: 429.1 | H24: #DIV/0! | I24: 275.017 | J24: 0 | K24: 0 | L24: 0 | M24: #DIV/0! | N24: #DIV/0! | O24: #DIV/0! | P24: 0 | T24: 5 | U24: 2420.52
B25: 泓洋 | C25: 71 | D25: -6 | E25: 19239.45 | F25: -0.5462 | G25: 270.98 | H25: -0.5079 | I25: 3905.2414 | J25: 0 | K25: 0 | L25: 0 | M25: #DIV/0! | N25: #DIV/0! | O25: #DIV/0! | P25: 0 | T25: 71 | U25: 23144.69
B26: 万海通 | C26: 80 | D26: -21 | E26: 32526.3 | F26: -0.2193 | G26: 406.58 | H26: -0.0143 | I26: 4400.272 | J26: 0 | K26: 0 | L26: 0 | M26: #DIV/0! | N26: #DIV/0! | O26: #DIV/0! | P26: 0 | T26: 80 | U26: 36926.57
B27: 华慧良修 | C27: 241 | D27: 55 | E27: 98230.14 | F27: 0.4545 | G27: 407.59 | H27: 0.1226 | I27: 0 | J27: 296 | K27: -98 | L27: 59685 | M27: -0.2291 | N27: 201.64 | O27: 0.0262 | P27: 0 | T27: 537 | U27: 157915.14
B28: 广州一鸣 | C28: 16 | D28: -22 | E28: 3157.37 | F28: -0.5479 | G28: 197.34 | H28: 0.0737 | I28: 880.0544 | J28: 0 | K28: 0 | L28: 0 | M28: #DIV/0! | N28: #DIV/0! | O28: #DIV/0! | P28: 0 | T28: 16 | U28: 4037.42
B29: 凯琪物流 | C29: 197 | D29: 107 | E29: 15304.09 | F29: 1.2594 | G29: 77.69 | H29: 0.0323 | I29: 11055.577 | J29: 0 | K29: 0 | L29: 0 | M29: #DIV/0! | N29: #DIV/0! | O29: #DIV/0! | P29: 0 | T29: 197 | U29: 26359.67
B30: 南宁亿邦 | C30: 449 | D30: -448 | E30: 98497.97 | F30: -0.5783 | G30: 219.37 | H30: -0.1576 | I30: 9405.5814 | J30: 0 | K30: 0 | L30: 0 | M30: #DIV/0! | N30: #DIV/0! | O30: #DIV/0! | P30: 0 | T30: 449 | U30: 107903.55
B31: 星之航 | C31: 32 | D31: 19 | E31: 8568.38 | F31: 2.0744 | G31: 267.76 | H31: 0.249 | I31: 0 | J31: 0 | K31: 0 | L31: 0 | M31: #DIV/0! | N31: #DIV/0! | O31: #DIV/0! | P31: 0 | T31: 32 | U31: 8568.38
B32: 广通 | C32: 0 | D32: 0 | E32: 0 | F32: #DIV/0! | G32: #DIV/0! | H32: #DIV/0! | I32: 0 | J32: 74 | K32: -2 | L32: 14572 | M32: -0.1233 | N32: 196.92 | O32: -0.0996 | P32: 14220.59 | T32: 74 | U32: 28792.59
B33: 汕头裕港 | C33: 0 | D33: 0 | E33: 0 | F33: #DIV/0! | G33: #DIV/0! | H33: #DIV/0! | I33: 0 | J33: 0 | K33: 0 | L33: 0 | M33: #DIV/0! | N33: #DIV/0! | O33: #DIV/0! | P33: 0 | T33: 0 | U33: 0
B34: 港信 | C34: 66 | D34: -14 | E34: 20075.16 | F34: -0.2775 | G34: 304.17 | H34: -0.1242 | I34: 3910.1068 | J34: 0 | K34: 0 | L34: 0 | M34: #DIV/0! | N34: #DIV/0! | O34: #DIV/0! | P34: 0 | T34: 66 | U34: 23985.27
B35: 外包总计 | C35: 8918 | D35: -312 | E35: 2287411.1 | F35: 0.0099 | G35: 256.49 | H35: 0.0452 | I35: 401685.56 | J35: 459 | K35: -64 | L35: 97369 | M35: -0.1012 | N35: 212.13 | O35: 0.0241 | P35: 35987.19 | Q35: 0 | R35: 0 | S35: 0 | T35: 9377 | U35: 2822452.9
A36: 自营外包总计 | C36: 18081 | D36: -52 | E36: 4441752.1 | F36: 0.0075 | G36: 245.66 | H36: 0.0104 | I36: 765055.64 | J36: 1466 | K36: -506 | L36: 335560 | M36: -0.0627 | N36: 228.89 | O36: 0.2608 | P36: 97428.28 | Q36: 1328445.1 | R36: 95091.52 | S36: 0 | T36: 19547 | U36: 7063332.7
O37: 环比增减 | U37: -626154.73 | V37: -558 | W37: -626154.73
C38: 箱量 | D38: 环比 | E38: 产值 | F38: 环比 | Q38: 净值 | U38: 6378639.3
A39: 全部干箱业务 | C39: 19547 | D39: -0.03 | E39: 7063333 | F39: -0.0814 | M39: 56.15363
A40: 中远海自营占比 | C40: 0.925 | E40: 0.6288
...

Sheet 2026年第19周
A1: 单位汇总报表 | X1: 自营箱量完成情况
A2: 业务类型 | C2: 中远海干箱 | J2: 第三方干箱 | P2: 其它费用 | T2: 合计 | X2: 生产周期 | Z2: {=MID(_wpsfn.SHEETSNAME(Z2),7,2)} -> 19
A3: 部门/单位 | C3: 箱量 | D3: 环比 | E3: 产值 | F3: 环比 | G3: 单箱 | H3: 环比 | I3: 移箱费 | J3: 箱量 | K3: 环比 | L3: 产值 | M3: 环比 | N3: 单箱 | O3: 环比 | P3: 冷箱产值 | Q3: 堆场产值 | R3: 其它 | S3: 现金收费 | T3: 箱量 | U3: 产值 | V3: 人均产出 | W3: 人员数量 | X3: 周目标箱量 | Y3: 完成差额 | Z3: 合计目标箱量 | AA3: 合计完成量 | AB3: 合计完成差额
A4: 自营 | B4: 深圳运营中心 | C4: {=SUM((LOOKUP(ROW($45:$182),IF($A$45:$A$182<>"",ROW($45:$182)),$A$45:$A$182)=B4)*$C$45:$C$182)} -> 280 | D4: =C4-'2025年18周'!C4 -> -216 | E4: {=SUM((LOOKUP(ROW($45:$182),IF($A$45:$A$182<>"",ROW($45:$182)),$A$45:$A$182)=B4)*$E$45:$E$182)} -> 96025.08 | F4: =(E4-'2025年18周'!E4)/'2025年18周'!E4 -> -0.4757 | G4: =E4/C4 -> 342.95 | H4: =(G4-'2025年18周'!G4)/'2025年18周'!G4 -> -0.0713 | I4: {=SUM((LOOKUP(ROW($45:$182),IF($A$45:$A$182<>"",ROW($45:$182)),$A$45:$A$182)=B4)*$I$45:$I$182)} -> 0 | J4: {=SUM((LOOKUP(ROW($45:$182),IF($A$45:$A$182<>"",ROW($45:$182)),$A$45:$A$182)=B4)*$J$45:$J$182)} -> 64 | K4: =J4-'2025年18周'!J4 -> -67 | L4: {=SUM((LOOKUP(ROW($45:$182),IF($A$45:$A$182<>"",ROW($45:$182)),$A$45:$A$182)=B4)*$L$45:$L$182)} -> 17921 | M4: =(L4-'2025年18周'!L4)/'2025年18周'!L4 -> -0.6163 | N4: =L4/J4 -> 280.02 | O4: =(N4-'2025年18周'!N4)/'2025年18周'!N4 -> -0.2146 | P4: {=SUM((LOOKUP(ROW($45:$182),IF($A$45:$A$182<>"",ROW($45:$182)),$A$45:$A$182)=B4)*$P$45:$P$182)} -> 1190.32 | Q4: =SUMIFS(第19周周填报数据!D:D,第19周周填报数据!B:B,B4,第19周周填报数据!I:I,"堆场仓储板块") -> 101075.4 | R4: =SUMIFS(第19周周填报数据!D:D,第19周周填报数据!B:B,B4,第19周周填报数据!I:I,"<>堆场仓储板块") -> 510 | S4: 0 | T4: =C4+J4 -> 344 | U4: =E4+L4+I4+P4+Q4+R4+S4 -> 216721.8 | V4: =U4/W4 -> 5160 | W4: 42 | X4: 900 | Y4: =T4-X4 -> -556 | Z4: =X4*$Z$2 -> 17100 | AA4: =自营2026周完成情况!BB35 -> 10160 | AB4: =AA4-Z4 -> -6940
B5: 广州运营中心 | C5: {=SUM((LOOKUP(ROW($45:$182),IF($A$45:$A$182<>"",ROW($45:$182)),$A$45:$A$182)=B5)*$C$45:$C$182)} -> 2073 | D5: =C5-'2025年18周'!C5 -> -776 | E5: {=SUM((LOOKUP(ROW($45:$182),IF($A$45:$A$182<>"",ROW($45:$182)),$A$45:$A$182)=B5)*$E$45:$E$182)} -> 296138.23 | F5: =(E5-'2025年18周'!E5)/'2025年18周'!E5 -> -0.313 | G5: =E5/C5 -> 142.85 | H5: =(G5-'2025年18周'!G5)/'2025年18周'!G5 -> -0.0558 | I5: {=SUM((LOOKUP(ROW($45:$182),IF($A$45:$A$182<>"",ROW($45:$182)),$A$45:$A$182)=B5)*$I$45:$I$182)} -> 136132.76 | J5: {=SUM((LOOKUP(ROW($45:$182),IF($A$45:$A$182<>"",ROW($45:$182)),$A$45:$A$182)=B5)*$J$45:$J$182)} -> 66 | K5: =J5-'2025年18周'!J5 -> -82 | L5: {=SUM((LOOKUP(ROW($45:$182),IF($A$45:$A$182<>"",ROW($45:$182)),$A$45:$A$182)=B5)*$L$45:$L$182)} -> 15558 | M5: =(L5-'2025年18周'!L5)/'2025年18周'!L5 -> -0.6369 | N5: =L5/J5 -> 235.73 | O5: =(N5-'2025年18周'!N5)/'2025年18周'!N5 -> -0.1857 | P5: {=SUM((LOOKUP(ROW($45:$182),IF($A$45:$A$182<>"",ROW($45:$182)),$A$45:$A$182)=B5)*$P$45:$P$182)} -> 10865.54 | Q5: =SUMIFS(第19周周填报数据!D:D,第19周周填报数据!B:B,B5,第19周周填报数据!I:I,"堆场仓储板块") -> 0 | R5: =SUMIFS(第19周周填报数据!D:D,第19周周填报数据!B:B,B5,第19周周填报数据!I:I,"<>堆场仓储板块") -> 11120 | T5: =C5+J5 -> 2139 | U5: =E5+L5+I5+P5+Q5+R5+S5 -> 469814.53 | V5: =U5/W5 -> 14237 | W5: 33 | X5: 2500 | Y5: =T5-X5 -> -361 | Z5: =X5*$Z$2 -> 47500 | AA5: =自营2026周完成情况!BB36 -> 51345 | AB5: =AA5-Z5 -> 3845
B6: 珠三角运营中心 | C6: {=SUM((LOOKUP(ROW($45:$182),IF($A$45:$A$182<>"",ROW($45:$182)),$A$45:$A$182)=B6)*$C$45:$C$182)} -> 1431 | D6: =C6-'2025年18周'!C6 -> -853 | E6: {=SUM((LOOKUP(ROW($45:$182),IF($A$45:$A$182<>"",ROW($45:$182)),$A$45:$A$182)=B6)*$E$45:$E$182)} -> 329095.39 | F6: =(E6-'2025年18周'!E6)/'2025年18周'!E6 -> -0.3665 | G6: =E6/C6 -> 229.98 | H6: =(G6-'2025年18周'!G6)/'2025年18周'!G6 -> 0.0112 | I6: {=SUM((LOOKUP(ROW($45:$182),IF($A$45:$A$182<>"",ROW($45:$182)),$A$45:$A$182)=B6)*$I$45:$I$182)} -> 74382.256 | J6: {=SUM((LOOKUP(ROW($45:$182),IF($A$45:$A$182<>"",ROW($45:$182)),$A$45:$A$182)=B6)*$J$45:$J$182)} -> 40 | K6: =J6-'2025年18周'!J6 -> -209 | L6: {=SUM((LOOKUP(ROW($45:$182),IF($A$45:$A$182<>"",ROW($45:$182)),$A$45:$A$182)=B6)*$L$45:$L$182)} -> 15397 | M6: =(L6-'2025年18周'!L6)/'2025年18周'!L6 -> -0.8144 | N6: =L6/J6 -> 384.93 | O6: =(N6-'2025年18周'!N6)/'2025年18周'!N6 -> 0.1552 | P6: {=SUM((LOOKUP(ROW($45:$182),IF($A$45:$A$182<>"",ROW($45:$182)),$A$45:$A$182)=B6)*$P$45:$P$182)} -> 0 | Q6: =SUMIFS(第19周周填报数据!D:D,第19周周填报数据!B:B,B6,第19周周填报数据!I:I,"堆场仓储板块") -> 6882 | R6: =SUMIFS(第19周周填报数据!D:D,第19周周填报数据!B:B,B6,第19周周填报数据!I:I,"<>堆场仓储板块") -> 0 | T6: =C6+J6 -> 1471 | U6: =E6+L6+I6+P6+Q6+R6+S6 -> 425756.65 | V6: =U6/W6 -> 7341 | W6: 58 | X6: 3000 | Y6: =T6-X6 -> -1529 | Z6: =X6*$Z$2 -> 57000 | AA6: =自营2026周完成情况!BB37 -> 38596 | AB6: =AA6-Z6 -> -18404
B7: 粤西运营中心 | C7: {=SUM((LOOKUP(ROW($45:$182),IF($A$45:$A$182<>"",ROW($45:$182)),$A$45:$A$182)=B7)*$C$45:$C$182)} -> 1038 | D7: =C7-'2025年18周'!C7 -> -293 | E7: {=SUM((LOOKUP(ROW($45:$182),IF($A$45:$A$182<>"",ROW($45:$182)),$A$45:$A$182)=B7)*$E$45:$E$182)} -> 215642.55 | F7: =(E7-'2025年18周'!E7)/'2025年18周'!E7 -> -0.3846 | G7: =E7/C7 -> 207.75 | H7: =(G7-'2025年18周'!G7)/'2025年18周'!G7 -> -0.2109 | I7: {=SUM((LOOKUP(ROW($45:$182),IF($A$45:$A$182<>"",ROW($45:$182)),$A$45:$A$182)=B7)*$I$45:$I$182)} -> 47005.053 | J7: {=SUM((LOOKUP(ROW($45:$182),IF($A$45:$A$182<>"",ROW($45:$182)),$A$45:$A$182)=B7)*$J$45:$J$182)} -> 96 | K7: =J7-'2025年18周'!J7 -> 53 | L7: {=SUM((LOOKUP(ROW($45:$182),IF($A$45:$A$182<>"",ROW($45:$182)),$A$45:$A$182)=B7)*$L$45:$L$182)} -> 17220 | M7: =(L7-'2025年18周'!L7)/'2025年18周'!L7 -> 0.4061 | N7: =L7/J7 -> 179.38 | O7: =(N7-'2025年18周'!N7)/'2025年18周'!N7 -> -0.3702 | P7: {=SUM((LOOKUP(ROW($45:$182),IF($A$45:$A$182<>"",ROW($45:$182)),$A$45:$A$182)=B7)*$P$45:$P$182)} -> 749.89 | Q7: =SUMIFS(第19周周填报数据!D:D,第19周周填报数据!B:B,B7,第19周周填报数据!I:I,"堆场仓储板块") -> 7155.66 | R7: =SUMIFS(第19周周填报数据!D:D,第19周周填报数据!B:B,B7,第19周周填报数据!I:I,"<>堆场仓储板块") -> 10505 | T7: =C7+J7 -> 1134 | U7: =E7+L7+I7+P7+Q7+R7+S7 -> 298278.15 | V7: =U7/W7 -> 14204 | W7: 21 | X7: 1100 | Y7: =T7-X7 -> 34 | Z7: =X7*$Z$2 -> 20900 | AA7: =自营2026周完成情况!BB38 -> 24386 | AB7: =AA7-Z7 -> 3486
B8: 北部湾运营中心 | C8: {=SUM((LOOKUP(ROW($45:$182),IF($A$45:$A$182<>"",ROW($45:$182)),$A$45:$A$182)=B8)*$C$45:$C$182)} -> 1535 | D8: =C8-'2025年18周'!C8 -> -422 | E8: {=SUM((LOOKUP(ROW($45:$182),IF($A$45:$A$182<>"",ROW($45:$182)),$A$45:$A$182)=B8)*$E$45:$E$182)} -> 451210.96 | F8: =(E8-'2025年18周'!E8)/'2025年18周'!E8 -> -0.2819 | G8: =E8/C8 -> 293.95 | H8: =(G8-'2025年18周'!G8)/'2025年18周'!G8 -> -0.0845 | I8: {=SUM((LOOKUP(ROW($45:$182),IF($A$45:$A$182<>"",ROW($45:$182)),$A$45:$A$182)=B8)*$I$45:$I$182)} -> 2035.1258 | J8: {=SUM((LOOKUP(ROW($45:$182),IF($A$45:$A$182<>"",ROW($45:$182)),$A$45:$A$182)=B8)*$J$45:$J$182)} -> 15 | K8: =J8-'2025年18周'!J8 -> 1 | L8: {=SUM((LOOKUP(ROW($45:$182),IF($A$45:$A$182<>"",ROW($45:$182)),$A$45:$A$182)=B8)*$L$45:$L$182)} -> 5543 | M8: =(L8-'2025年18周'!L8)/'2025年18周'!L8 -> 1.1712 | N8: =L8/J8 -> 369.53 | O8: =(N8-'2025年18周'!N8)/'2025年18周'!N8 -> 1.0264 | P8: {=SUM((LOOKUP(ROW($45:$182),IF($A$45:$A$182<>"",ROW($45:$182)),$A$45:$A$182)=B8)*$P$45:$P$182)} -> 0 | Q8: =SUMIFS(第19周周填报数据!D:D,第19周周填报数据!B:B,B8,第19周周填报数据!I:I,"堆场仓储板块") -> 69338 | R8: =SUMIFS(第19周周填报数据!D:D,第19周周填报数据!B:B,B8,第19周周填报数据!I:I,"<>堆场仓储板块") -> 10395 | T8: =C8+J8 -> 1550 | U8: =E8+L8+I8+P8+Q8+R8+S8 -> 538522.09 | V8: =U8/W8 -> 16829 | W8: 32 | X8: 1500 | Y8: =T8-X8 -> 50 | Z8: =X8*$Z$2 -> 28500 | AA8: =自营2026周完成情况!BB39 -> 39046 | AB8: =AA8-Z8 -> 10546
B9: 南岗分公司 | C9: {=SUM((LOOKUP(ROW($45:$182),IF($A$45:$A$182<>"",ROW($45:$182)),$A$45:$A$182)=B9)*$C$45:$C$182)} -> 150 | D9: =C9-'2025年18周'!C9 -> -96 | E9: {=SUM((LOOKUP(ROW($45:$182),IF($A$45:$A$182<>"",ROW($45:$182)),$A$45:$A$182)=B9)*$E$45:$E$182)} -> 32503.36 | F9: =(E9-'2025年18周'!E9)/'2025年18周'!E9 -> -0.2248 | G9: =E9/C9 -> 216.69 | H9: =(G9-'2025年18周'!G9)/'2025年18周'!G9 -> 0.2714 | I9: {=SUM((LOOKUP(ROW($45:$182),IF($A$45:$A$182<>"",ROW($45:$182)),$A$45:$A$182)=B9)*$I$45:$I$182)} -> 5689.9952 | J9: {=SUM((LOOKUP(ROW($45:$182),IF($A$45:$A$182<>"",ROW($45:$182)),$A$45:$A$182)=B9)*$J$45:$J$182)} -> 40 | K9: =J9-'2025年18周'!J9 -> -382 | L9: {=SUM((LOOKUP(ROW($45:$182),IF($A$45:$A$182<>"",ROW($45:$182)),$A$45:$A$182)=B9)*$L$45:$L$182)} -> 12625 | M9: =(L9-'2025年18周'!L9)/'2025年18周'!L9 -> -0.7518 | N9: =L9/J9 -> 315.63 | O9: =(N9-'2025年18周'!N9)/'2025年18周'!N9 -> 1.6182 | P9: {=SUM((LOOKUP(ROW($45:$182),IF($A$45:$A$182<>"",ROW($45:$182)),$A$45:$A$182)=B9)*$P$45:$P$182)} -> 728.33 | Q9: =SUMIFS(第19周周填报数据!D:D,第19周周填报数据!B:B,B9,第19周周填报数据!I:I,"堆场仓储板块")+SUMIFS(第19周周填报数据!D:D,第19周周填报数据!B:B,"市场部拆装箱",第19周周填报数据!I:I,"堆场仓储板块") -> 48988 | R9: =SUMIFS(第19周周填报数据!D:D,第19周周填报数据!B:B,B9,第19周周填报数据!I:I,"<>堆场仓储板块")+SUMIFS(第19周周填报数据!D:D,第19周周填报数据!B:B,"市场部拆装箱",第19周周填报数据!I:I,"<>堆场仓储板块") -> 121715 | S9: 0 | T9: =C9+J9 -> 190 | U9: =E9+L9+I9+P9+Q9+R9+S9 -> 222249.69 | V9: =U9/W9 -> 12347 | W9: 18 | X9: 600 | Y9: =T9-X9 -> -410 | Z9: =X9*$Z$2 -> 11400 | AA9: =自营2026周完成情况!BB40 -> 11367 | AB9: =AA9-Z9 -> -33
B10: 自营总计 | C10: =SUM(C4:C9) -> 6507 | D10: =C10-'2025年18周'!C10 -> -2656 | E10: =SUM(E4:E9) -> 1420615.6 | F10: =(E10-'2025年18周'!E10)/'2025年18周'!E10 -> -0.3406 | G10: =E10/C10 -> 218.32 | H10: =(G10-'2025年18周'!G10)/'2025年18周'!G10 -> -0.0714 | I10: =SUM(I4:I9) -> 265245.19 | J10: =SUM(J4:J9) -> 321 | K10: =J10-'2025年18周'!J10 -> -686 | L10: =SUM(L4:L9) -> 84264 | M10: =(L10-'2025年18周'!L10)/'2025年18周'!L10 -> -0.6462 | N10: =L10/J10 -> 262.5 | O10: =(N10-'2025年18周'!N10)/'2025年18周'!N10 -> 0.1097 | P10: =SUM(P4:P9) -> 13534.08 | Q10: =SUM(Q4:Q9) -> 233439.06 | R10: =SUM(R4:R9) -> 154245 | S10: =SUM(S4:S9) -> 0 | T10: =SUM(T4:T9) -> 6828 | U10: =SUM(U4:U9) -> 2171342.9 | V10: =U10/W10 -> 10644 | W10: =SUM(W4:W9) -> 204 | X10: 9600 | Y10: =T10-X10 -> -2772 | Z10: =SUM(Z4:Z9) -> 182400 | AA10: =自营2026周完成情况!BB41 -> 174900 | AB10: =AA10-Z10 -> -7500
A11: 合作供应商 | B11: 广州弘运 | C11: {=SUM((LOOKUP(ROW($45:$182),IF($A$45:$A$182<>"",ROW($45:$182)),$A$45:$A$182)=B11)*$C$45:$C$182)} -> 1360 | D11: =C11-'2025年18周'!C11 -> -1152 | E11: {=SUM((LOOKUP(ROW($45:$182),IF($A$45:$A$182<>"",ROW($45:$182)),$A$45:$A$182)=B11)*$E$45:$E$182)} -> 336980.69 | F11: =(E11-'2025年18周'!E11)/'2025年18周'!E11 -> -0.5242 | G11: =E11/C11 -> 247.78 | H11: =(G11-'2025年18周'!G11)/'2025年18周'!G11 -> -0.1213 | I11: {=SUM((LOOKUP(ROW($45:$182),IF($A$45:$A$182<>"",ROW($45:$182)),$A$45:$A$182)=B11)*$I$45:$I$182)} -> 49615.6 | J11: {=SUM((LOOKUP(ROW($45:$182),IF($A$45:$A$182<>"",ROW($45:$182)),$A$45:$A$182)=B11)*$J$45:$J$182)} -> 0 | K11: =J11-'2025年18周'!J11 -> -20 | L11: {=SUM((LOOKUP(ROW($45:$182),IF($A$45:$A$182<>"",ROW($45:$182)),$A$45:$A$182)=B11)*$L$45:$L$182)} -> 0 | M11: =(L11-'2025年18周'!L11)/'2025年18周'!L11 -> -1 | N11: =L11/J11 -> #DIV/0! | O11: =(N11-'2025年18周'!N11)/'2025年18周'!N11 -> #DIV/0! | P11: {=SUM((LOOKUP(ROW($45:$182),IF($A$45:$A$182<>"",ROW($45:$182)),$A$45:$A$182)=B11)*$P$45:$P$182)} -> 8684.86 | T11: =C11+J11 -> 1360 | U11: =E11+L11+I11+P11+Q11+R11+S11 -> 395281.15
B12: 钦州弘运 | C12: {=SUM((LOOKUP(ROW($45:$182),IF($A$45:$A$182<>"",ROW($45:$182)),$A$45:$A$182)=B12)*$C$45:$C$182)} -> 706 | D12: =C12-'2025年18周'!C12 -> 8 | E12: {=SUM((LOOKUP(ROW($45:$182),IF($A$45:$A$182<>"",ROW($45:$182)),$A$45:$A$182)=B12)*$E$45:$E$182)} -> 180154.38 | F12: =(E12-'2025年18周'!E12)/'2025年18周'!E12 -> 0.1154 | G12: =E12/C12 -> 255.18 | H12: =(G12-'2025年18周'!G12)/'2025年18周'!G12 -> 0.1028 | I12: {=SUM((LOOKUP(ROW($45:$182),IF($A$45:$A$182<>"",ROW($45:$182)),$A$45:$A$182)=B12)*$I$45:$I$182)} -> 27416.656 | J12: {=SUM((LOOKUP(ROW($45:$182),IF($A$45:$A$182<>"",ROW($45:$182)),$A$45:$A$182)=B12)*$J$45:$J$182)} -> 9 | K12: =J12-'2025年18周'!J12 -> 5 | L12: {=SUM((LOOKUP(ROW($45:$182),IF($A$45:$A$182<>"",ROW($45:$182)),$A$45:$A$182)=B12)*$L$45:$L$182)} -> 3734 | M12: =(L12-'2025年18周'!L12)/'2025年18周'!L12 -> 0.8783 | N12: =L12/J12 -> 414.89 | O12: =(N12-'2025年18周'!N12)/'2025年18周'!N12 -> -0.1652 | P12: {=SUM((LOOKUP(ROW($45:$182),IF($A$45:$A$182<>"",ROW($45:$182)),$A$45:$A$182)=B12)*$P$45:$P$182)} -> 158.6 | T12: =C12+J12 -> 715 | U12: =E12+L12+I12+P12+Q12+R12+S12 -> 211463.64
B13: 弘运天浩 | C13: {=SUM((LOOKUP(ROW($45:$182),IF($A$45:$A$182<>"",ROW($45:$182)),$A$45:$A$182)=B13)*$C$45:$C$182)} -> 478 | D13: =C13-'2025年18周'!C13 -> -139 | E13: {=SUM((LOOKUP(ROW($45:$182),IF($A$45:$A$182<>"",ROW($45:$182)),$A$45:$A$182)=B13)*$E$45:$E$182)} -> 63454.18 | F13: =(E13-'2025年18周'!E13)/'2025年18周'!E13 -> -0.5239 | G13: =E13/C13 -> 132.75 | H13: =(G13-'2025年18周'!G13)/'2025年18周'!G13 -> -0.3855 | I13: {=SUM((LOOKUP(ROW($45:$182),IF($A$45:$A$182<>"",ROW($45:$182)),$A$45:$A$182)=B13)*$I$45:$I$182)} -> 30169.996 | J13: {=SUM((LOOKUP(ROW($45:$182),IF($A$45:$A$182<>"",ROW($45:$182)),$A$45:$A$182)=B13)*$J$45:$J$182)} -> 4 | K13: =J13-'2025年18周'!J13 -> -47 | L13: {=SUM((LOOKUP(ROW($45:$182),IF($A$45:$A$182<>"",ROW($45:$182)),$A$45:$A$182)=B13)*$L$45:$L$182)} -> 1039 | M13: =(L13-'2025年18周'!L13)/'2025年18周'!L13 -> -0.9227 | N13: =L13/J13 -> 259.75 | O13: =(N13-'2025年18周'!N13)/'2025年18周'!N13 -> -0.015 | P13: {=SUM((LOOKUP(ROW($45:$182),IF($A$45:$A$182<>"",ROW($45:$182)),$A$45:$A$182)=B13)*$P$45:$P$182)} -> 0 | T13: =C13+J13 -> 482 | U13: =E13+L13+I13+P13+Q13+R13+S13 -> 94663.18
B14: 万年红 | C14: {=SUM((LOOKUP(ROW($45:$182),IF($A$45:$A$182<>"",ROW($45:$182)),$A$45:$A$182)=B14)*$C$45:$C$182)} -> 295 | D14: =C14-'2025年18周'!C14 -> -45 | E14: {=SUM((LOOKUP(ROW($45:$182),IF($A$45:$A$182<>"",ROW($45:$182)),$A$45:$A$182)=B14)*$E$45:$E$182)} -> 28237.5 | F14: =(E14-'2025年18周'!E14)/'2025年18周'!E14 -> -0.4264 | G14: =E14/C14 -> 95.72 | H14: =(G14-'2025年18周'!G14)/'2025年18周'!G14 -> -0.3389 | I14: {=SUM((LOOKUP(ROW($45:$182),IF($A$45:$A$182<>"",ROW($45:$182)),$A$45:$A$182)=B14)*$I$45:$I$182)} -> 18624.995 | J14: {=SUM((LOOKUP(ROW($45:$182),IF($A$45:$A$182<>"",ROW($45:$182)),$A$45:$A$182)=B14)*$J$45:$J$182)} -> 0 | K14: =J14-'2025年18周'!J14 -> 0 | L14: {=SUM((LOOKUP(ROW($45:$182),IF($A$45:$A$182<>"",ROW($45:$182)),$A$45:$A$182)=B14)*$L$45:$L$182)} -> 0 | M14: =(L14-'2025年18周'!L14)/'2025年18周'!L14 -> #DIV/0! | N14: =L14/J14 -> #DIV/0! | O14: =(N14-'2025年18周'!N14)/'2025年18周'!N14 -> #DIV/0! | P14: {=SUM((LOOKUP(ROW($45:$182),IF($A$45:$A$182<>"",ROW($45:$182)),$A$45:$A$182)=B14)*$P$45:$P$182)} -> 0 | T14: =C14+J14 -> 295 | U14: =E14+L14+I14+P14+Q14+R14+S14 -> 46862.5
B15: 裕丰 | C15: {=SUM((LOOKUP(ROW($45:$182),IF($A$45:$A$182<>"",ROW($45:$182)),$A$45:$A$182)=B15)*$C$45:$C$182)} -> 313 | D15: =C15-'2025年18周'!C15 -> -13 | E15: {=SUM((LOOKUP(ROW($45:$182),IF($A$45:$A$182<>"",ROW($45:$182)),$A$45:$A$182)=B15)*$E$45:$E$182)} -> 70417.13 | F15: =(E15-'2025年18周'!E15)/'2025年18周'!E15 -> -0.0661 | G15: =E15/C15 -> 224.97 | H15: =(G15-'2025年18周'!G15)/'2025年18周'!G15 -> -0.0273 | I15: {=SUM((LOOKUP(ROW($45:$182),IF($A$45:$A$182<>"",ROW($45:$182)),$A$45:$A$182)=B15)*$I$45:$I$182)} -> 17575.913 | J15: {=SUM((LOOKUP(ROW($45:$182),IF($A$45:$A$182<>"",ROW($45:$182)),$A$45:$A$182)=B15)*$J$45:$J$182)} -> 0 | K15: =J15-'2025年18周'!J15 -> 0 | L15: {=SUM((LOOKUP(ROW($45:$182),IF($A$45:$A$182<>"",ROW($45:$182)),$A$45:$A$182)=B15)*$L$45:$L$182)} -> 0 | M15: =(L15-'2025年18周'!L15)/'2025年18周'!L15 -> #DIV/0! | N15: =L15/J15 -> #DIV/0! | O15: =(N15-'2025年18周'!N15)/'2025年18周'!N15 -> #DIV/0! | P15: {=SUM((LOOKUP(ROW($45:$182),IF($A$45:$A$182<>"",ROW($45:$182)),$A$45:$A$182)=B15)*$P$45:$P$182)} -> 0 | T15: =C15+J15 -> 313 | U15: =E15+L15+I15+P15+Q15+R15+S15 -> 87993.04
B16: 本港 | C16: {=SUM((LOOKUP(ROW($45:$182),IF($A$45:$A$182<>"",ROW($45:$182)),$A$45:$A$182)=B16)*$C$45:$C$182)} -> 18 | D16: =C16-'2025年18周'!C16 -> 0 | E16: {=SUM((LOOKUP(ROW($45:$182),IF($A$45:$A$182<>"",ROW($45:$182)),$A$45:$A$182)=B16)*$E$45:$E$182)} -> 7671.77 | F16: =(E16-'2025年18周'!E16)/'2025年18周'!E16 -> 1.0272 | G16: =E16/C16 -> 426.21 | H16: =(G16-'2025年18周'!G16)/'2025年18周'!G16 -> 1.0273 | I16: {=SUM((LOOKUP(ROW($45:$182),IF($A$45:$A$182<>"",ROW($45:$182)),$A$45:$A$182)=B16)*$I$45:$I$182)} -> 1090.0192 | J16: {=SUM((LOOKUP(ROW($45:$182),IF($A$45:$A$182<>"",ROW($45:$182)),$A$45:$A$182)=B16)*$J$45:$J$182)} -> 0 | K16: =J16-'2025年18周'!J16 -> 0 | L16: {=SUM((LOOKUP(ROW($45:$182),IF($A$45:$A$182<>"",ROW($45:$182)),$A$45:$A$182)=B16)*$L$45:$L$182)} -> 0 | M16: =(L16-'2025年18周'!L16)/'2025年18周'!L16 -> #DIV/0! | N16: =L16/J16 -> #DIV/0! | O16: =(N16-'2025年18周'!N16)/'2025年18周'!N16 -> #DIV/0! | P16: {=SUM((LOOKUP(ROW($45:$182),IF($A$45:$A$182<>"",ROW($45:$182)),$A$45:$A$182)=B16)*$P$45:$P$182)} -> 0 | T16: =C16+J16 -> 18 | U16: =E16+L16+I16+P16+Q16+R16+S16 -> 8761.79
B17: 坚迅 | C17: {=SUM((LOOKUP(ROW($45:$182),IF($A$45:$A$182<>"",ROW($45:$182)),$A$45:$A$182)=B17)*$C$45:$C$182)} -> 722 | D17: =C17-'2025年18周'!C17 -> 2 | E17: {=SUM((LOOKUP(ROW($45:$182),IF($A$45:$A$182<>"",ROW($45:$182)),$A$45:$A$182)=B17)*$E$45:$E$182)} -> 206348.91 | F17: =(E17-'2025年18周'!E17)/'2025年18周'!E17 -> 0.0563 | G17: =E17/C17 -> 285.8 | H17: =(G17-'2025年18周'!G17)/'2025年18周'!G17 -> 0.0533 | I17: {=SUM((LOOKUP(ROW($45:$182),IF($A$45:$A$182<>"",ROW($45:$182)),$A$45:$A$182)=B17)*$I$45:$I$182)} -> 52706.995 | J17: {=SUM((LOOKUP(ROW($45:$182),IF($A$45:$A$182<>"",ROW($45:$182)),$A$45:$A$182)=B17)*$J$45:$J$182)} -> 0 | K17: =J17-'2025年18周'!J17 -> -3 | L17: {=SUM((LOOKUP(ROW($45:$182),IF($A$45:$A$182<>"",ROW($45:$182)),$A$45:$A$182)=B17)*$L$45:$L$182)} -> 0 | M17: =(L17-'2025年18周'!L17)/'2025年18周'!L17 -> -1 | N17: =L17/J17 -> #DIV/0! | O17: =(N17-'2025年18周'!N17)/'2025年18周'!N17 -> #DIV/0! | P17: {=SUM((LOOKUP(ROW($45:$182),IF($A$45:$A$182<>"",ROW($45:$182)),$A$45:$A$182)=B17)*$P$45:$P$182)} -> 0 | T17: =C17+J17 -> 722 | U17: =E17+L17+I17+P17+Q17+R17+S17 -> 259055.9
B18: 浚得兴 | C18: {=SUM((LOOKUP(ROW($45:$182),IF($A$45:$A$182<>"",ROW($45:$182)),$A$45:$A$182)=B18)*$C$45:$C$182)} -> 576 | D18: =C18-'2025年18周'!C18 -> -67 | E18: {=SUM((LOOKUP(ROW($45:$182),IF($A$45:$A$182<>"",ROW($45:$182)),$A$45:$A$182)=B18)*$E$45:$E$182)} -> 158850.28 | F18: =(E18-'2025年18周'!E18)/'2025年18周'!E18 -> -0.1194 | G18: =E18/C18 -> 275.78 | H18: =(G18-'2025年18周'!G18)/'2025年18周'!G18 -> -0.017 | I18: {=SUM((LOOKUP(ROW($45:$182),IF($A$45:$A$182<>"",ROW($45:$182)),$A$45:$A$182)=B18)*$I$45:$I$182)} -> 34420.808 | J18: {=SUM((LOOKUP(ROW($45:$182),IF($A$45:$A$182<>"",ROW($45:$182)),$A$45:$A$182)=B18)*$J$45:$J$182)} -> 0 | K18: =J18-'2025年18周'!J18 -> 0 | L18: {=SUM((LOOKUP(ROW($45:$182),IF($A$45:$A$182<>"",ROW($45:$182)),$A$45:$A$182)=B18)*$L$45:$L$182)} -> 0 | M18: =(L18-'2025年18周'!L18)/'2025年18周'!L18 -> #DIV/0! | N18: =L18/J18 -> #DIV/0! | O18: =(N18-'2025年18周'!N18)/'2025年18周'!N18 -> #DIV/0! | P18: {=SUM((LOOKUP(ROW($45:$182),IF($A$45:$A$182<>"",ROW($45:$182)),$A$45:$A$182)=B18)*$P$45:$P$182)} -> 0 | T18: =C18+J18 -> 576 | U18: =E18+L18+I18+P18+Q18+R18+S18 -> 193271.09
B19: 深圳天河 | C19: {=SUM((LOOKUP(ROW($45:$182),IF($A$45:$A$182<>"",ROW($45:$182)),$A$45:$A$182)=B19)*$C$45:$C$182)} -> 0 | D19: =C19-'2025年18周'!C19 -> -5 | E19: {=SUM((LOOKUP(ROW($45:$182),IF($A$45:$A$182<>"",ROW($45:$182)),$A$45:$A$182)=B19)*$E$45:$E$182)} -> 0 | F19: =(E19-'2025年18周'!E19)/'2025年18周'!E19 -> -1 | G19: =E19/C19 -> #DIV/0! | H19: =(G19-'2025年18周'!G19)/'2025年18周'!G19 -> #DIV/0! | I19: {=SUM((LOOKUP(ROW($45:$182),IF($A$45:$A$182<>"",ROW($45:$182)),$A$45:$A$182)=B19)*$I$45:$I$182)} -> 0 | J19: {=SUM((LOOKUP(ROW($45:$182),IF($A$45:$A$182<>"",ROW($45:$182)),$A$45:$A$182)=B19)*$J$45:$J$182)} -> 0 | K19: =J19-'2025年18周'!J19 -> 0 | L19: {=SUM((LOOKUP(ROW($45:$182),IF($A$45:$A$182<>"",ROW($45:$182)),$A$45:$A$182)=B19)*$L$45:$L$182)} -> 0 | M19: =(L19-'2025年18周'!L19)/'2025年18周'!L19 -> #DIV/0! | N19: =L19/J19 -> #DIV/0! | O19: =(N19-'2025年18周'!N19)/'2025年18周'!N19 -> #DIV/0! | P19: {=SUM((LOOKUP(ROW($45:$182),IF($A$45:$A$182<>"",ROW($45:$182)),$A$45:$A$182)=B19)*$P$45:$P$182)} -> 0 | T19: =C19+J19 -> 0 | U19: =E19+L19+I19+P19+Q19+R19+S19 -> 0
B20: 信步 | C20: {=SUM((LOOKUP(ROW($45:$182),IF($A$45:$A$182<>"",ROW($45:$182)),$A$45:$A$182)=B20)*$C$45:$C$182)} -> 497 | D20: =C20-'2025年18周'!C20 -> -286 | E20: {=SUM((LOOKUP(ROW($45:$182),IF($A$45:$A$182<>"",ROW($45:$182)),$A$45:$A$182)=B20)*$E$45:$E$182)} -> 84757.71 | F20: =(E20-'2025年18周'!E20)/'2025年18周'!E20 -> -0.3618 | G20: =E20/C20 -> 170.54 | H20: =(G20-'2025年18周'!G20)/'2025年18周'!G20 -> 0.0054 | I20: {=SUM((LOOKUP(ROW($45:$182),IF($A$45:$A$182<>"",ROW($45:$182)),$A$45:$A$182)=B20)*$I$45:$I$182)} -> 28856.051 | J20: {=SUM((LOOKUP(ROW($45:$182),IF($A$45:$A$182<>"",ROW($45:$182)),$A$45:$A$182)=B20)*$J$45:$J$182)} -> 10 | K20: =J20-'2025年18周'!J20 -> -1 | L20: {=SUM((LOOKUP(ROW($45:$182),IF($A$45:$A$182<>"",ROW($45:$182)),$A$45:$A$182)=B20)*$L$45:$L$182)} -> 3100 | M20: =(L20-'2025年18周'!L20)/'2025年18周'!L20 -> -0.1077 | N20: =L20/J20 -> 310 | O20: =(N20-'2025年18周'!N20)/'2025年18周'!N20 -> -0.0184 | P20: {=SUM((LOOKUP(ROW($45:$182),IF($A$45:$A$182<>"",ROW($45:$182)),$A$45:$A$182)=B20)*$P$45:$P$182)} -> 0 | T20: =C20+J20 -> 507 | U20: =E20+L20+I20+P20+Q20+R20+S20 -> 116713.76
B21: 万永联 | C21: {=SUM((LOOKUP(ROW($45:$182),IF($A$45:$A$182<>"",ROW($45:$182)),$A$45:$A$182)=B21)*$C$45:$C$182)} -> 94 | D21: =C21-'2025年18周'!C21 -> -67 | E21: {=SUM((LOOKUP(ROW($45:$182),IF($A$45:$A$182<>"",ROW($45:$182)),$A$45:$A$182)=B21)*$E$45:$E$182)} -> 15637.99 | F21: =(E21-'2025年18周'!E21)/'2025年18周'!E21 -> -0.4488 | G21: =E21/C21 -> 166.36 | H21: =(G21-'2025年18周'!G21)/'2025年18周'!G21 -> -0.056 | I21: {=SUM((LOOKUP(ROW($45:$182),IF($A$45:$A$182<>"",ROW($45:$182)),$A$45:$A$182)=B21)*$I$45:$I$182)} -> 0 | J21: {=SUM((LOOKUP(ROW($45:$182),IF($A$45:$A$182<>"",ROW($45:$182)),$A$45:$A$182)=B21)*$J$45:$J$182)} -> 0 | K21: =J21-'2025年18周'!J21 -> 0 | L21: {=SUM((LOOKUP(ROW($45:$182),IF($A$45:$A$182<>"",ROW($45:$182)),$A$45:$A$182)=B21)*$L$45:$L$182)} -> 0 | M21: =(L21-'2025年18周'!L21)/'2025年18周'!L21 -> #DIV/0! | N21: =L21/J21 -> #DIV/0! | O21: =(N21-'2025年18周'!N21)/'2025年18周'!N21 -> #DIV/0! | P21: {=SUM((LOOKUP(ROW($45:$182),IF($A$45:$A$182<>"",ROW($45:$182)),$A$45:$A$182)=B21)*$P$45:$P$182)} -> 0 | T21: =C21+J21 -> 94 | U21: =E21+L21+I21+P21+Q21+R21+S21 -> 15637.99
B22: 辉成 | C22: {=SUM((LOOKUP(ROW($45:$182),IF($A$45:$A$182<>"",ROW($45:$182)),$A$45:$A$182)=B22)*$C$45:$C$182)} -> 133 | D22: =C22-'2025年18周'!C22 -> -64 | E22: {=SUM((LOOKUP(ROW($45:$182),IF($A$45:$A$182<>"",ROW($45:$182)),$A$45:$A$182)=B22)*$E$45:$E$182)} -> 25832.76 | F22: =(E22-'2025年18周'!E22)/'2025年18周'!E22 -> -0.381 | G22: =E22/C22 -> 194.23 | H22: =(G22-'2025年18周'!G22)/'2025年18周'!G22 -> -0.0831 | I22: {=SUM((LOOKUP(ROW($45:$182),IF($A$45:$A$182<>"",ROW($45:$182)),$A$45:$A$182)=B22)*$I$45:$I$182)} -> 7995.1666 | J22: {=SUM((LOOKUP(ROW($45:$182),IF($A$45:$A$182<>"",ROW($45:$182)),$A$45:$A$182)=B22)*$J$45:$J$182)} -> 0 | K22: =J22-'2025年18周'!J22 -> 0 | L22: {=SUM((LOOKUP(ROW($45:$182),IF($A$45:$A$182<>"",ROW($45:$182)),$A$45:$A$182)=B22)*$L$45:$L$182)} -> 0 | M22: =(L22-'2025年18周'!L22)/'2025年18周'!L22 -> #DIV/0! | N22: =L22/J22 -> #DIV/0! | O22: =(N22-'2025年18周'!N22)/'2025年18周'!N22 -> #DIV/0! | P22: {=SUM((LOOKUP(ROW($45:$182),IF($A$45:$A$182<>"",ROW($45:$182)),$A$45:$A$182)=B22)*$P$45:$P$182)} -> 0 | T22: =C22+J22 -> 133 | U22: =E22+L22+I22+P22+Q22+R22+S22 -> 33827.93
B23: 万建达 | C23: {=SUM((LOOKUP(ROW($45:$182),IF($A$45:$A$182<>"",ROW($45:$182)),$A$45:$A$182)=B23)*$C$45:$C$182)} -> 329 | D23: =C23-'2025年18周'!C23 -> -412 | E23: {=SUM((LOOKUP(ROW($45:$182),IF($A$45:$A$182<>"",ROW($45:$182)),$A$45:$A$182)=B23)*$E$45:$E$182)} -> 117602.03 | F23: =(E23-'2025年18周'!E23)/'2025年18周'!E23 -> -0.5767 | G23: =E23/C23 -> 357.45 | H23: =(G23-'2025年18周'!G23)/'2025年18周'!G23 -> -0.0465 | I23: {=SUM((LOOKUP(ROW($45:$182),IF($A$45:$A$182<>"",ROW($45:$182)),$A$45:$A$182)=B23)*$I$45:$I$182)} -> 0 | J23: {=SUM((LOOKUP(ROW($45:$182),IF($A$45:$A$182<>"",ROW($45:$182)),$A$45:$A$182)=B23)*$J$45:$J$182)} -> 0 | K23: =J23-'2025年18周'!J23 -> 0 | L23: {=SUM((LOOKUP(ROW($45:$182),IF($A$45:$A$182<>"",ROW($45:$182)),$A$45:$A$182)=B23)*$L$45:$L$182)} -> 0 | M23: =(L23-'2025年18周'!L23)/'2025年18周'!L23 -> #DIV/0! | N23: =L23/J23 -> #DIV/0! | O23: =(N23-'2025年18周'!N23)/'2025年18周'!N23 -> #DIV/0! | P23: {=SUM((LOOKUP(ROW($45:$182),IF($A$45:$A$182<>"",ROW($45:$182)),$A$45:$A$182)=B23)*$P$45:$P$182)} -> 0 | T23: =C23+J23 -> 329 | U23: =E23+L23+I23+P23+Q23+R23+S23 -> 117602.03
... B34: 港信 | C34: {=SUM((LOOKUP(ROW($45:$182),IF($A$45:$A$182<>"",ROW($45:$182)),$A$45:$A$182)=B34)*$C$45:$C$182)} -> 46 | D34: =C34-'2025年18周'!C34 -> -20 | E34: {=SUM((LOOKUP(ROW($45:$182),IF($A$45:$A$182<>"",ROW($45:$182)),$A$45:$A$182)=B34)*$E$45:$E$182)} -> 7821.98 | F34: =(E34-'2025年18周'!E34)/'2025年18周'!E34 -> -0.6104 | G34: =E34/C34 -> 170.04 | H34: =(G34-'2025年18周'!G34)/'2025年18周'!G34 -> -0.441 | I34: {=SUM((LOOKUP(ROW($45:$182),IF($A$45:$A$182<>"",ROW($45:$182)),$A$45:$A$182)=B34)*$I$45:$I$182)} -> 2790.0472 | J34: {=SUM((LOOKUP(ROW($45:$182),IF($A$45:$A$182<>"",ROW($45:$182)),$A$45:$A$182)=B34)*$J$45:$J$182)} -> 0 | K34: =J34-'2025年18周'!J34 -> 0 | L34: {=SUM((LOOKUP(ROW($45:$182),IF($A$45:$A$182<>"",ROW($45:$182)),$A$45:$A$182)=B34)*$L$45:$L$182)} -> 0 | M34: =(L34-'2025年18周'!L34)/'2025年18周'!L34 -> #DIV/0! | N34: =L34/J34 -> #DIV/0! | O34: =(N34-'2025年18周'!N34)/'2025年18周'!N34 -> #DIV/0! | P34: {=SUM((LOOKUP(ROW($45:$182),IF($A$45:$A$182<>"",ROW($45:$182)),$A$45:$A$182)=B34)*$P$45:$P$182)} -> 0 | T34: =C34+J34 -> 46 | U34: =E34+L34+I34+P34+Q34+R34+S34 -> 10612.03
B35: 外包总计 | C35: =SUM(C11:C34) -> 6508 | D35: =C35-'2025年18周'!C35 -> -2410 | E35: =SUM(E11:E34) -> 1573497.9 | F35: =(E35-'2025年18周'!E35)/'2025年18周'!E35 -> -0.3121 | G35: =E35/C35 -> 241.78 | H35: =(G35-'2025年18周'!G35)/'2025年18周'!G35 -> -0.0574 | I35: =SUM(I11:I34) -> 293378.59 | J35: =SUM(J11:J34) -> 241 | K35: =J35-'2025年18周'!J35 -> -218 | L35: =SUM(L11:L34) -> 44003 | M35: =(L35-'2025年18周'!L35)/'2025年18周'!L35 -> -0.5481 | N35: =L35/J35 -> 182.59 | O35: =(N35-'2025年18周'!N35)/'2025年18周'!N35 -> -0.1393 | P35: =SUM(P11:P34) -> 15836.79 | Q35: =SUM(Q11:Q34) -> 0 | R35: =SUM(R11:R34) -> 0 | S35: =SUM(S11:S30) -> 0 | T35: =SUM(T11:T34) -> 6749 | U35: =SUM(U11:U34) -> 1926716.3
A36: 自营外包总计 | C36: =C10+C35 -> 13015 | D36: =C36-'2025年18周'!C36 -> -5066 | E36: =E10+E35 -> 2994113.5 | F36: =(E36-'2025年18周'!E36)/'2025年18周'!E36 -> -0.3259 | G36: =E36/C36 -> 230.05 | H36: =(G36-'2025年18周'!G36)/'2025年18周'!G36 -> -0.0635 | I36: =I10+I35 -> 558623.77 | J36: =J10+J35 -> 562 | K36: =J36-'2025年18周'!J36 -> -904 | L36: =L10+L35 -> 128267 | M36: =(L36-'2025年18周'!L36)/'2025年18周'!L36 -> -0.6178 | N36: =L36/J36 -> 228.23 | O36: =(N36-'2025年18周'!N36)/'2025年18周'!N36 -> -0.0029 | P36: =P10+P35 -> 29370.87 | Q36: =Q10+Q35 -> 233439.06 | R36: =R10+R35 -> 154245 | S36: =S10+S35 -> 0 | T36: =T10+T35 -> 13577 | U36: =U10+U35 -> 4098059.2
C37: =IF(C36<>SUMIFS(周检修业务统计数据!E:E,周检修业务统计数据!C:C,"干箱",周检修业务统计数据!D:D,"COS"),"箱量有错","") | J37: =IF(J36<>SUMIFS(周检修业务统计数据!E:E,周检修业务统计数据!C:C,"干箱",周检修业务统计数据!D:D,"<>COS"),"箱量有错","") | O37: 环比增减 | U37: =U36-'2025年18周'!U36 -> -2965273.5 | V37: =T36-'2025年18周'!T36 -> -5970 | W37: =U36-'2025年18周'!U36 -> -2965273.5
C38: 箱量 | D38: 环比 | E38: 产值 | F38: 环比 | Q38: 净值 | U38: =(E36++L36+P36+S36)/1.13+(I36+Q36+R36)/1.06 -> 3681903.8
A39: 全部干箱业务 | C39: =T36 -> 13577 | D39: =(T36-'2025年18周'!T36)/'2025年18周'!T36 -> -0.31 | E39: =U36 -> 4098059 | F39: =(U36-'2025年18周'!U36)/'2025年18周'!U36 -> -0.4198 | M39: =E36/(1.13*7*10000) -> 37.852257
A40: 中远海自营占比 | C40: =C36/C39 -> 0.9586 | E40: =E36/E39 -> 0.7306
A41: 第三方业务占比 | C41: =J36/C39 -> 0.0414 | E41: =L36/E39 -> 0.0313
A42: 网点明细报表
A43: 业务类型 | C43: 中远海干箱 | J43: 第三方干箱 | P43: 其它费用 | T43: 合计 | X43: 分网点自营箱量完成情况 | AC43: 网点业务情况备注
A44: 部门/单位 | C44: 箱量 | D44: 环比 | E44: 产值 | F44: 环比 | G44: 单箱 | H44: 环比 | I44: 移箱费 | J44: 箱量 | K44: 环比 | L44: 产值 | M44: 环比 | N44: 单箱 | O44: 环比 | P44: 冷箱产值 | Q44: 堆场产值 | R44: 其它 | S44: 现金收费 | T44: 箱量 | U44: 产值 | V44: 人均产出 | W44: 修理人员数量 | X44: 周目标箱量 | Y44: 完成差额 | Z44: 合计目标箱量 | AA44: 合计完成量 | AB44: 合计完成差额
A45: 南岗分公司 | B45: 南岗堆场 | C45: =SUMIFS(周检修业务统计数据!E:E,周检修业务统计数据!B:B,B45,周检修业务统计数据!C:C,"干箱",周检修业务统计数据!D:D,"COS") -> 60 | D45: =C45-'2025年18周'!C45 -> -11 | E45: =(SUMIFS(周检修业务统计数据!I:I,周检修业务统计数据!B:B,B45,周检修业务统计数据!C:C,"干箱",周检修业务统计数据!D:D,"COS")+SUMIFS(周检修业务统计数据!J:J,周检修业务统计数据!B:B,B45,周检修业务统计数据!C:C,"干箱",周检修业务统计数据!D:D,"COS"))*1.13 -> 21637 | F45: =(E45-'2025年18周'!E45)/'2025年18周'!E45 -> 0.0249 | G45: =E45/C45 -> 361 | H45: =(G45-'2025年18周'!G45)/'2025年18周'!G45 -> 0.2155 | I45: =SUMIFS(周检修业务统计数据!L:L,周检修业务统计数据!B:B,B45,周检修业务统计数据!C:C,"干箱",周检修业务统计数据!D:D,"COS")*1.06 -> 0 | J45: =SUMIFS(周检修业务统计数据!E:E,周检修业务统计数据!B:B,B45,周检修业务统计数据!C:C,"干箱",周检修业务统计数据!D:D,"<>COS") -> 40 | K45: =J45-'2025年18周'!J45 -> -355 | L45: =(SUMIFS(周检修业务统计数据!I:I,周检修业务统计数据!B:B,B45,周检修业务统计数据!C:C,"干箱",周检修业务统计数据!D:D,"<>COS")+SUMIFS(周检修业务统计数据!J:J,周检修业务统计数据!B:B,B45,周检修业务统计数据!C:C,"干箱",周检修业务统计数据!D:D,"<>COS"))*1.13++SUMIFS(周检修业务统计数据!L:L,周检修业务统计数据!B:B,B45,周检修业务统计数据!C:C,"干箱",周检修业务统计数据!D:D,"<>COS")*1.06 -> 12624.93 | M45: =(L45-'2025年18周'!L45)/'2025年18周'!L45 -> -0.7379 | N45: =L45/J45 -> 316 | O45: =(N45-'2025年18周'!N45)/'2025年18周'!N45 -> 1.5902 | P45: =(SUMIFS(周检修业务统计数据!I:I,周检修业务统计数据!B:B,B45,周检修业务统计数据!C:C,"<>干箱")+SUMIFS(周检修业务统计数据!J:J,周检修业务统计数据!B:B,B45,周检修业务统计数据!C:C,"<>干箱"))*1.13++SUMIFS(周检修业务统计数据!L:L,周检修业务统计数据!B:B,B45,周检修业务统计数据!C:C,"<>干箱")*1.06 -> 728.33 | Q45: 48988 | S45: =S188 -> 0 | T45: =C45+J45 -> 100 | U45: =E45+L45+I45+P45+Q45+R45+S45 -> 83978 | V45: =(E45+L45+E46+L46)/W45 -> 6447 | W45: 7 | X45: 600 | Y45: =SUM(T45:T46)-X45 -> -410 | Z45: =X45*$Z$2 -> 11400 | AA45: =自营2026周完成情况!BB55 -> 7898 | AB45: =AA45-Z45 -> -3502
A46: 南岗分公司 | B46: 东江仓码头 | C46: =SUMIFS(周检修业务统计数据!E:E,周检修业务统计数据!B:B,B46,周检修业务统计数据!C:C,"干箱",周检修业务统计数据!D:D,"COS") -> 90 | D46: =C46-'2025年18周'!C46 -> -85 | E46: =(SUMIFS(周检修业务统计数据!I:I,周检修业务统计数据!B:B,B46,周检修业务统计数据!C:C,"干箱",周检修业务统计数据!D:D,"COS")+SUMIFS(周检修业务统计数据!J:J,周检修业务统计数据!B:B,B46,周检修业务统计数据!C:C,"干箱",周检修业务统计数据!D:D,"COS"))*1.13 -> 10866.36 | F46: =(E46-'2025年18周'!E46)/'2025年18周'!E46 -> -0.478 | G46: =E46/C46 -> 121 | H46: =(G46-'2025年18周'!G46)/'2025年18周'!G46 -> 0.0168 | I46: =SUMIFS(周检修业务统计数据!L:L,周检修业务统计数据!B:B,B46,周检修业务统计数据!C:C,"干箱",周检修业务统计数据!D:D,"COS")*1.06 -> 5689.9952 | J46: =SUMIFS(周检修业务统计数据!E:E,周检修业务统计数据!B:B,B46,周检修业务统计数据!C:C,"干箱",周检修业务统计数据!D:D,"<>COS") -> 0 | K46: =J46-'2025年18周'!J46 -> -27 | L46: =(SUMIFS(周检修业务统计数据!I:I,周检修业务统计数据!B:B,B46,周检修业务统计数据!C:C,"干箱",周检修业务统计数据!D:D,"<>COS")+SUMIFS(周检修业务统计数据!J:J,周检修业务统计数据!B:B,B46,周检修业务统计数据!C:C,"干箱",周检修业务统计数据!D:D,"<>COS"))*1.13++SUMIFS(周检修业务统计数据!L:L,周检修业务统计数据!B:B,B46,周检修业务统计数据!C:C,"干箱",周检修业务统计数据!D:D,"<>COS")*1.06 -> 0 | M46: =(L46-'2025年18周'!L46)/'2025年18周'!L46 -> -1 | N46: =L46/J46 -> #DIV/0! | O46: =(N46-'2025年18周'!N46)/'2025年18周'!N46 -> #DIV/0! | P46: =(SUMIFS(周检修业务统计数据!I:I,周检修业务统计数据!B:B,B46,周检修业务统计数据!C:C,"<>干箱")+SUMIFS(周检修业务统计数据!J:J,周检修业务统计数据!B:B,B46,周检修业务统计数据!C:C,"<>干箱"))*1.13++SUMIFS(周检修业务统计数据!L:L,周检修业务统计数据!B:B,B46,周检修业务统计数据!C:C,"<>干箱")*1.06 -> 0 | S46: =S189 -> 0 | T46: =C46+J46 -> 90 | U46: =E46+L46+I46+P46+Q46+R46+S46 -> 16556 | Z46: =X46*$Z$2 -> 0 | AA46: =自营2026周完成情况!BB56 -> 3469 | AB46: =AA46-Z46 -> 3469
A47: 深圳运营中心 | B47: 深圳大铲湾 | C47: =SUMIFS(周检修业务统计数据!E:E,周检修业务统计数据!B:B,B47,周检修业务统计数据!C:C,"干箱",周检修业务统计数据!D:D,"COS") -> 102 | D47: =C47-'2025年18周'!C47 -> -72 | E47: =(SUMIFS(周检修业务统计数据!I:I,周检修业务统计数据!B:B,B47,周检修业务统计数据!C:C,"干箱",周检修业务统计数据!D:D,"COS")+SUMIFS(周检修业务统计数据!J:J,周检修业务统计数据!B:B,B47,周检修业务统计数据!C:C,"干箱",周检修业务统计数据!D:D,"COS"))*1.13 -> 42053.97 | F47: =(E47-'2025年18周'!E47)/'2025年18周'!E47 -> -0.3931 | G47: =E47/C47 -> 412 | H47: =(G47-'2025年18周'!G47)/'2025年18周'!G47 -> 0.0352 | I47: =SUMIFS(周检修业务统计数据!L:L,周检修业务统计数据!B:B,B47,周检修业务统计数据!C:C,"干箱",周检修业务统计数据!D:D,"COS")*1.06 -> 0 | J47: =SUMIFS(周检修业务统计数据!E:E,周检修业务统计数据!B:B,B47,周检修业务统计数据!C:C,"干箱",周检修业务统计数据!D:D,"<>COS") -> 0 | K47: =J47-'2025年18周'!J47 -> -1 | L47: =(SUMIFS(周检修业务统计数据!I:I,周检修业务统计数据!B:B,B47,周检修业务统计数据!C:C,"干箱",周检修业务统计数据!D:D,"<>COS")+SUMIFS(周检修业务统计数据!J:J,周检修业务统计数据!B:B,B47,周检修业务统计数据!C:C,"干箱",周检修业务统计数据!D:D,"<>COS"))*1.13++SUMIFS(周检修业务统计数据!L:L,周检修业务统计数据!B:B,B47,周检修业务统计数据!C:C,"干箱",周检修业务统计数据!D:D,"<>COS")*1.06 -> 0 | M47: =(L47-'2025年18周'!L47)/'2025年18周'!L47 -> -1 | N47: =L47/J47 -> #DIV/0! | O47: =(N47-'2025年18周'!N47)/'2025年18周'!N47 -> #DIV/0! | P47: =(SUMIFS(周检修业务统计数据!I:I,周检修业务统计数据!B:B,B47,周检修业务统计数据!C:C,"<>干箱")+SUMIFS(周检修业务统计数据!J:J,周检修业务统计数据!B:B,B47,周检修业务统计数据!C:C,"<>干箱"))*1.13++SUMIFS(周检修业务统计数据!L:L,周检修业务统计数据!B:B,B47,周检修业务统计数据!C:C,"<>干箱")*1.06 -> 0 | S47: =S190 -> 0 | T47: =C47+J47 -> 102 | U47: =E47+L47+I47+P47+Q47+R47+S47 -> 42054 | V47: =(E47+L47)/W47 -> 10513 | W47: 4 | X47: 400 | Y47: =T47-X47 -> -298 | Z47: =X47*$Z$2 -> 7600 | AA47: =自营2026周完成情况!BB57 -> 2578 | AB47: =AA47-Z47 -> -5022
A48: 华慧良修 | B48: 深圳蛇口堆场 | C48: =SUMIFS(周检修业务统计数据!E:E,周检修业务统计数据!B:B,B48,周检修业务统计数据!C:C,"干箱",周检修业务统计数据!D:D,"COS") -> 174 | D48: =C48-'2025年18周'!C48 -> -67 | E48: =(SUMIFS(周检修业务统计数据!I:I,周检修业务统计数据!B:B,B48,周检修业务统计数据!C:C,"干箱",周检修业务统计数据!D:D,"COS")+SUMIFS(周检修业务统计数据!J:J,周检修业务统计数据!B:B,B48,周检修业务统计数据!C:C,"干箱",周检修业务统计数据!D:D,"COS"))*1.13 -> 74503.25 | F48: =(E48-'2025年18周'!E48)/'2025年18周'!E48 -> -0.2415 | G48: =E48/C48 -> 428 | H48: =(G48-'2025年18周'!G48)/'2025年18周'!G48 -> 0.049 | I48: =SUMIFS(周检修业务统计数据!L:L,周检修业务统计数据!B:B,B48,周检修业务统计数据!C:C,"干箱",周检修业务统计数据!D:D,"COS")*1.06 -> 0 | J48: =SUMIFS(周检修业务统计数据!E:E,周检修业务统计数据!B:B,B48,周检修业务统计数据!C:C,"干箱",周检修业务统计数据!D:D,"<>COS") -> 147 | K48: =J48-'2025年18周'!J48 -> -108 | L48: =(SUMIFS(周检修业务统计数据!I:I,周检修业务统计数据!B:B,B48,周检修业务统计数据!C:C,"干箱",周检修业务统计数据!D:D,"<>COS")+SUMIFS(周检修业务统计数据!J:J,周检修业务统计数据!B:B,B48,周检修业务统计数据!C:C,"干箱",周检修业务统计数据!D:D,"<>COS"))*1.13++SUMIFS(周检修业务统计数据!L:L,周检修业务统计数据!B:B,B48,周检修业务统计数据!C:C,"干箱",周检修业务统计数据!D:D,"<>COS")*1.06 -> 23804.4 | M48: =(L48-'2025年18周'!L48)/'2025年18周'!L48 -> -0.5441 | N48: =L48/J48 -> 162 | O48: =(N48-'2025年18周'!N48)/'2025年18周'!N48 -> -0.2098 | P48: =(SUMIFS(周检修业务统计数据!I:I,周检修业务统计数据!B:B,B48,周检修业务统计数据!C:C,"<>干箱")+SUMIFS(周检修业务统计数据!J:J,周检修业务统计数据!B:B,B48,周检修业务统计数据!C:C,"<>干箱"))*1.13++SUMIFS(周检修业务统计数据!L:L,周检修业务统计数据!B:B,B48,周检修业务统计数据!C:C,"<>干箱")*1.06 -> 0 | Q48: 78519.5 | S48: =S191 -> 0 | T48: =C48+J48 -> 321 | U48: =E48+L48+I48+P48+Q48+R48+S48 -> 176827 | V48: =(E48+L48)/W48 -> 14044 | W48: 7 | X48: 400 | Y48: =T48-X48 -> -79 | Z48: =X48*$Z$2 -> 7600 | AA48: =自营2026周完成情况!BB58 -> 7033 | AB48: =AA48-Z48 -> -567
A49: 深圳运营中心 | B49: 汕头广澳 | C49: =SUMIFS(周检修业务统计数据!E:E,周检修业务统计数据!B:B,B49,周检修业务统计数据!C:C,"干箱",周检修业务统计数据!D:D,"COS") -> 0 | D49: =C49-'2025年18周'!C49 -> 0 | E49: =(SUMIFS(周检修业务统计数据!I:I,周检修业务统计数据!B:B,B49,周检修业务统计数据!C:C,"干箱",周检修业务统计数据!D:D,"COS")+SUMIFS(周检修业务统计数据!J:J,周检修业务统计数据!B:B,B49,周检修业务统计数据!C:C,"干箱",周检修业务统计数据!D:D,"COS"))*1.13 -> 0 | F49: =(E49-'2025年18周'!E49)/'2025年18周'!E49 -> #DIV/0! | G49: =E49/C49 -> #DIV/0! | H49: =(G49-'2025年18周'!G49)/'2025年18周'!G49 -> #DIV/0! | I49: =SUMIFS(周检修业务统计数据!L:L,周检修业务统计数据!B:B,B49,周检修业务统计数据!C:C,"干箱",周检修业务统计数据!D:D,"COS")*1.06 -> 0 | J49: =SUMIFS(周检修业务统计数据!E:E,周检修业务统计数据!B:B,B49,周检修业务统计数据!C:C,"干箱",周检修业务统计数据!D:D,"<>COS") -> 0 | K49: =J49-'2025年18周'!J49 -> 0 | L49: =(SUMIFS(周检修业务统计数据!I:I,周检修业务统计数据!B:B,B49,周检修业务统计数据!C:C,"干箱",周检修业务统计数据!D:D,"<>COS")+SUMIFS(周检修业务统计数据!J:J,周检修业务统计数据!B:B,B49,周检修业务统计数据!C:C,"干箱",周检修业务统计数据!D:D,"<>COS"))*1.13++SUMIFS(周检修业务统计数据!L:L,周检修业务统计数据!B:B,B49,周检修业务统计数据!C:C,"干箱",周检修业务统计数据!D:D,"<>COS")*1.06 -> 0 | M49: =(L49-'2025年18周'!L49)/'2025年18周'!L49 -> #DIV/0! | N49: =L49/J49 -> #DIV/0! | O49: =(N49-'2025年18周'!N49)/'2025年18周'!N49 -> #DIV/0! | P49: =(SUMIFS(周检修业务统计数据!I:I,周检修业务统计数据!B:B,B49,周检修业务统计数据!C:C,"<>干箱")+SUMIFS(周检修业务统计数据!J:J,周检修业务统计数据!B:B,B49,周检修业务统计数据!C:C,"<>干箱"))*1.13++SUMIFS(周检修业务统计数据!L:L,周检修业务统计数据!B:B,B49,周检修业务统计数据!C:C,"<>干箱")*1.06 -> 0 | S49: =S192 -> 0 | T49: =C49+J49 -> 0 | U49: =E49+L49+I49+P49+Q49+R49+S49 -> 0 | V49: =(E49+L49)/W49 -> #DIV/0! | W49: 0 | X49: 500 | Y49: =SUM(T49:T51)-X49 -> -258 | Z49: =X49*$Z$2 -> 9500 | AA49: =SUM(自营2026周完成情况!BB59:BB61) -> 7340 | AB49: =AA49-Z49 -> -2160
A50: 深圳运营中心 | B50: 汕头堆场 | C50: =SUMIFS(周检修业务统计数据!E:E,周检修业务统计数据!B:B,B50,周检修业务统计数据!C:C,"干箱",周检修业务统计数据!D:D,"COS") -> 178 | D50: =C50-'2025年18周'!C50 -> -144 | E50: =(SUMIFS(周检修业务统计数据!I:I,周检修业务统计数据!B:B,B50,周检修业务统计数据!C:C,"干箱",周检修业务统计数据!D:D,"COS")+SUMIFS(周检修业务统计数据!J:J,周检修业务统计数据!B:B,B50,周检修业务统计数据!C:C,"干箱",周检修业务统计数据!D:D,"COS"))*1.13 -> 53971.11 | F50: =(E50-'2025年18周'!E50)/'2025年18周'!E50 -> -0.526 | G50: =E50/C50 -> 303 | H50: =(G50-'2025年18周'!G50)/'2025年18周'!G50 -> -0.1441 | I50: =SUMIFS(周检修业务统计数据!L:L,周检修业务统计数据!B:B,B50,周检修业务统计数据!C:C,"干箱",周检修业务统计数据!D:D,"COS")*1.06 -> 0 | J50: =SUMIFS(周检修业务统计数据!E:E,周检修业务统计数据!B:B,B50,周检修业务统计数据!C:C,"干箱",周检修业务统计数据!D:D,"<>COS") -> 64 | K50: =J50-'2025年18周'!J50 -> -66 | L50: =(SUMIFS(周检修业务统计数据!I:I,周检修业务统计数据!B:B,B50,周检修业务统计数据!C:C,"干箱",周检修业务统计数据!D:D,"<>COS")+SUMIFS(周检修业务统计数据!J:J,周检修业务统计数据!B:B,B50,周检修业务统计数据!C:C,"干箱",周检修业务统计数据!D:D,"<>COS"))*1.13++SUMIFS(周检修业务统计数据!L:L,周检修业务统计数据!B:B,B50,周检修业务统计数据!C:C,"干箱",周检修业务统计数据!D:D,"<>COS")*1.06 -> 17920.62 | M50: =(L50-'2025年18周'!L50)/'2025年18周'!L50 -> -0.6122 | N50: =L50/J50 -> 280 | O50: =(N50-'2025年18周'!N50)/'2025年18周'!N50 -> -0.2113 | P50: =(SUMIFS(周检修业务统计数据!I:I,周检修业务统计数据!B:B,B50,周检修业务统计数据!C:C,"<>干箱")+SUMIFS(周检修业务统计数据!J:J,周检修业务统计数据!B:B,B50,周检修业务统计数据!C:C,"<>干箱"))*1.13++SUMIFS(周检修业务统计数据!L:L,周检修业务统计数据!B:B,B50,周检修业务统计数据!C:C,"<>干箱")*1.06 -> 1190.32 | Q50: 14189.5 | R50: 120 | S50: =S193 -> 0 | T50: =C50+J50 -> 242 | U50: =E50+L50+I50+P50+Q50+R50+S50 -> 87392 | V50: =(E50+L50)/W50 -> 7189 | W50: 10
...

Sheet 自营2026周完成情况
A1: 财务月（2025年） | B1: 1月 | C1: 2月 | D1: 3月 | E1: 4月 | F1: 5月 | G1: 6月 | H1: 7月 | I1: 8月 | J1: 9月 | K1: 10月 | L1: 11月 | M1: 12月
A2: 财务月天数 | B2: 31 | C2: 31 | D2: 28 | E2: 31 | F2: 30 | G2: 31 | H2: 30 | I2: 31 | J2: 31 | K2: 30 | L2: 31 | M2: 30
A3: 财务月产值指标比100% | B3: =B4/29000 -> 0.078 | C3: =C4/29000 -> 0.061 | D3: =D4/29000 -> 0.078 | E3: =E4/29000 -> 0.082 | F3: =F4/29000 -> 0.082 | G3: =G4/29000 -> 0.089 | H3: =H4/29000 -> 0.089 | I3: =I4/29000 -> 0.089 | ... M3: =M4/29000 -> 0.083
A4: 财务月指标（年25900万） | B4: 2268 | C4: 1780 | D4: 2268 | E4: 2368 | F4: 2368 | G4: 2590 | H4: 2590 | I4: 2590 | J4: 2590 | K4: 2505 | L4: 2668 | M4: 2415
A5: 每天产值指标 | B5: =B4/B2 -> 73.16 | C5: =C4/C2 -> 57.42 | D5: =D4/D2 -> 81 | E5: =E4/E2 -> 76.39 | F5: =F4/F2 -> 78.93 | G5: =G4/G2 -> 83.55 | H5: =H4/H2 -> 86.33 | I5: =I4/I2 -> 83.55 | ... M5: =M4/M2 -> 80.5
A6: 生产月完成指标
A7: 财务月完成指标
A8: 财务月度指标完成比例 | B8: =B7/B4 -> 0 | C8: =C7/C4 -> 0 | D8: =D7/D4 -> 0 | E8: =E7/E4 -> 0 | F8: =F7/F4 -> 0 | G8: =G7/G4 -> 0 | H8: =H7/H4 -> 0 | I8: =I7/I4 -> 0 | ... L8: =L7/L4 -> 0
A11: 自营每周产值（2025年） | B11: 第1周 | C11: 第2周 | D11: 第3周 | E11: 第4周 | F11: 第5周 | G11: 第6周 | H11: 第7周 | I11: 第8周 | J11: 第9周 | K11: 第10周 | L11: 第11周 | M11: 第12周 | N11: 第13周 | O11: 第14周 | P11: 第15周 | Q11: 第16周 | R11: 第17周 | S11: 第18周 | T11: 第19周 | U11: 第20周 | V11: 第21周 | W11: 第22周 | X11: 第23周 | Y11: 第24周 | Z11: 第25周 | AA11: 第26周 | AB11: 第27周 | AC11: 第28周 | AD11: 第29周 | AE11: 第30周 | AF11: 第31周 | AG11: 第32周 | AH11: 第33周 | AI11: 第34周 | AJ11: 第35周 | AK11: 第36周 | AL11: 第37周 | AM11: 第38周 | AN11: 第39周 | AO11: 第40周 | AP11: 第41周 | AQ11: 第42周 | AR11: 第43周 | AS11: 第44周 | AT11: 第45周 | AU11: 第46周 | AV11: 第47周 | AW11: 第48周 | AX11: 第49周 | AY11: 第50周 | AZ11: 第51周 | BA11: 第52周 | BB11: 合计
A12: 生产周起始时间 | B12: 1225-1231 | C12: 0101-0107 | D12: 0108-0114 | E12: 0115-0121 | F12: 0122-0128 | G12: 0229-0204 | H12: 0205-0211 | I12: 0212-0218 | J12: 0219-0225 | K12: 0226-0304 | L12: 0305-0311 | M12: 0312-0328 | N12: 0319-0325 | O12: 0326-0401 | P12: 0402-0408 | Q12: 0409-0415 | R12: 0416-0422 | S12: 0423-0429 | T12: 0430-0506
A13: 生产周产值指标（万元） | B13: =7*$B$5 -> 512.12 | C13: =7*$B$5 -> 512.12 | D13: =7*$B$5 -> 512.12 | E13: =7*$B$5 -> 512.12 | F13: =B5*3+4*C5 -> 449.16 | G13: =$C$5*7 -> 401.94 | H13: =$C$5*7 -> 401.94 | I13: =$C$5*7 -> 401.94 | J13: =C5*5+D5*2 -> 449.1 | K13: =$D$5*7 -> 567 | L13: =$D$5*7 -> 567 | M13: =$D$5*7 -> 567 | N13: =$D$5*5+$E$5*2 -> 557.78 | O13: =$E$5*7 -> 534.73 | P13: =$E$5*7 -> 534.73 | Q13: =$E$5*7 -> 534.73 | R13: =$E$5*7 -> 534.73 | S13: =$E$5*6+$F$5*1 -> 537.27 | T13: =$F$5*7 -> 552.51 | U13: =$F$5*7 -> 552.51 | V13: =$F$5*7 -> 552.51 | W13: =$F$5*7 -> 552.51 | X13: =$F$5*3+$G$5*4 -> 570.99 | Y13: =$G$5*7 -> 584.85 | Z13: =$G$5*7 -> 584.85 | AA13: =$G$5*7 -> 584.85 | AB13: =$G$5*4+$H$5*3 -> 593.19 | AC13: =$H$5*7 -> 604.31 | AD13: =$H$5*7 -> 604.31 | AE13: =$H$5*7 -> 604.31 | AF13: =$H$5*7 -> 604.31 | AG13: =$I$5*7 -> 584.85 | AH13: =$I$5*7 -> 584.85 | AI13: =$I$5*7 -> 584.85 | AJ13: =$I$5*7 -> 584.85 | AK13: =$I$5*4+$J$5*3 -> 584.85 | AL13: =$J$5*7 -> 584.85 | AM13: =$J$5*7 -> 584.85 | AN13: =$J$5*7 -> 584.85 | AO13: =$J$5*7 -> 584.85 | AP13: =$J$5*7 -> 584.85 | AQ13: =$K$5*7 -> 584.5 | AR13: =$K$5*7 -> 584.5 | AS13: =$K$5*7 -> 584.5 | AT13: =$L$5*7 -> 602.42 | AU13: =$L$5*7 -> 602.42 | AV13: =$L$5*7 -> 602.42 | AW13: =$L$5*7 -> 602.42 | AX13: =$L$5*3+$M$5*4 -> 580.18 | AY13: =$M$5*7 -> 563.5 | AZ13: =$M$5*7 -> 563.5 | BA13: =$M$5*7 -> 563.5 | BB13: =SUM(B13:BA13) -> 28915.9
A14: 生产周实际完成产值（元） | B14: =B52 -> 5530553.3 | C14: =C52 -> 4852687.7 | D14: =D52 -> 6290487.2 | E14: =E52 -> 6214755.6 | F14: =F52 -> 6629699.8 | G14: =G52 -> 5427768.5 | H14: =H52 -> 5318554.3 | I14: =I52 -> 1824749.4 | ... BA14: =BA52 -> 0 | BB14: =SUM(B14:BA14) -> 99153639
A15: 生产周指标完成情况 | B15: =B14/(B13*10000) -> 1.0799 | C15: =C14/(C13*10000) -> 0.9476 | D15: =D14/(D13*10000) -> 1.2283 | E15: =E14/(E13*10000) -> 1.2135 | F15: =F14/(F13*10000) -> 1.476 | G15: =G14/(G13*10000) -> 1.3504 | H15: =H14/(H13*10000) -> 1.3232 | I15: =I14/(I13*10000) -> 0.454 | ... BA15: =BA14/(BA13*10000) -> 0
A17: 生产周累积产值完成指标 | B17: =BB14/(SUMIF(B14:BA14,"<>0 ",B13:BA13)*10000) -> 1.0286
A18: 完成全年总产值指标比 | B18: =BE52 -> 0.3419
A19: 生产时间与全年时间占比 | B19: =BF52 -> 0.3654
A21: 自营每周（2025年） | B21: 周累计箱量 | C21: 周累计量同比 | D21: 周累计产值(万) | E21: 周累计产值同比（万） | F21: 当周完成箱量 | G21: 当周指标差额
A22: 深圳运营中心 | B22: =BB35 -> 10160 | C22: =BC35 -> -6505 | D22: =BB45/10000 -> 1235 | E22: =BC45/10000 -> 484 | F22: ='2026年第19周'!T4 -> 344 | G22: ='2026年第19周'!Y4 -> -556
A23: 广州运营中心 | B23: =BB36 -> 51345 | C23: =BC36 -> -276 | D23: =BB46/10000 -> 1194 | E23: =BC46/10000 -> -92 | F23: ='2026年第19周'!T5 -> 2139 | G23: ='2026年第19周'!Y5 -> -361
A24: 珠三角运营中心 | B24: =BB37 -> 38596 | C24: =BC37 -> -8326 | D24: =BB47/10000 -> 1156 | E24: =BC47/10000 -> -191 | F24: ='2026年第19周'!T6 -> 1471 | G24: ='2026年第19周'!Y6 -> -1529
A25: 粤西 | B25: =BB38 -> 24386 | C25: =BC38 -> 3060 | D25: =BB48/10000 -> 826 | E25: =BC48/10000 -> 70 | F25: ='2026年第19周'!T7 -> 1134 | G25: ='2026年第19周'!Y7 -> 34
A26: 北部湾 | B26: =BB39 -> 39046 | C26: =BC39 -> 10062 | D26: =BB49/10000 -> 1279 | E26: =BC49/10000 -> 132 | F26: ='2026年第19周'!T8 -> 1550 | G26: ='2026年第19周'!Y8 -> 50
A27: 南岗分公司 | B27: =BB40 -> 11367 | C27: =BC40 -> 4307 | D27: =BB50/10000 -> 593 | E27: =BC50/10000 -> 95 | F27: ='2026年第19周'!T9 -> 190 | G27: ='2026年第19周'!Y9 -> -410
A28: 自营总计 | B28: =BB41 -> 174900 | C28: =BC41 -> 2322 | D28: =BB51/10000 -> 6283 | E28: =BC51/10000 -> 498 | F28: ='2026年第19周'!T10 -> 6828 | G28: ='2026年第19周'!Y10 -> -2772
A29: 总计完成 | B29: =BB42 -> 333785 | C29: =BC42 -> 48141 | D29: =BB52/10000 -> 9915 | E29: =BC52/10000 -> 1506 | F29: ='2026年第19周'!T36 -> 13577
A34: 自营每周箱量（2026年） | B34: 第1周 | C34: 第2周 | D34: 第3周 | E34: 第4周 | F34: 第5周 | G34: 第6周 | H34: 第7周 | I34: 第8周 | J34: 第9周 | K34: 第10周 | L34: 第11周 | M34: 第12周 | N34: 第13周 | O34: 第14周 | P34: 第15周 | Q34: 第16周 | R34: 第17周 | S34: 第18周 | T34: 第19周 | U34: 第20周 | V34: 第21周 | W34: 第22周 | X34: 第23周 | Y34: 第24周 | Z34: 第25周 | AA34: 第26周 | AB34: 第27周 | AC34: 第28周 | AD34: 第29周 | AE34: 第30周 | AF34: 第31周 | AG34: 第32周 | AH34: 第33周 | AI34: 第34周 | AJ34: 第35周 | AK34: 第36周 | AL34: 第37周 | AM34: 第38周 | AN34: 第39周 | AO34: 第40周 | AP34: 第41周 | AQ34: 第42周 | AR34: 第43周 | AS34: 第44周 | AT34: 第45周 | AU34: 第46周 | AV34: 第47周 | AW34: 第48周 | AX34: 第49周 | AY34: 第50周 | AZ34: 第51周 | BA34: 第52周 | BB34: 合计 | BC34: 同比2025年
A35: 深圳运营中心 | B35: 781 | C35: 710 | D35: 634 | E35: 686 | F35: 618 | G35: 569 | H35: 589 | I35: 50 | J35: 182 | K35: 446 | L35: 435 | M35: 576 | N35: 613 | O35: 694 | P35: 356 | Q35: 691 | R35: 559 | S35: 627 | T35: 344 | AY35: 0 | AZ35: 0 | BA35: 0 | BB35: =SUM(B35:BA35) -> 10160 | BC35: =BB35-(SUMIF(B35:BA35,"<>0",B100:BA100)) -> -6505
A36: 广州运营中心 | B36: 3534 | C36: 2523 | D36: 3511 | E36: 2946 | F36: 2919 | G36: 2620 | H36: 2562 | I36: 555 | J36: 336 | K36: 2462 | L36: 3368 | M36: 3252 | N36: 2947 | O36: 3285 | P36: 3088 | Q36: 3153 | R36: 3148 | S36: 2997 | T36: 2139 | BB36: =SUM(B36:BA36) -> 51345 | BC36: =BB36-(SUMIF(B36:BA36,"<>0",B101:BA101)) -> -276
A37: 珠三角运营中心 | B37: 2618 | C37: 2250 | D37: 2408 | E37: 2412 | F37: 2609 | G37: 1913 | H37: 1391 | I37: 225 | J37: 204 | K37: 1396 | L37: 2577 | M37: 2345 | N37: 2907 | O37: 2347 | P37: 2257 | Q37: 2447 | R37: 2286 | S37: 2533 | T37: 1471 | BB37: =SUM(B37:BA37) -> 38596 | BC37: =BB37-(SUMIF(B37:BA37,"<>0",B102:BA102)) -> -8326
A38: 粤西 | B38: 1141 | C38: 1225 | D38: 1596 | E38: 1220 | F38: 1478 | G38: 1750 | H38: 1847 | I38: 732 | J38: 403 | K38: 811 | L38: 1294 | M38: 1251 | N38: 1523 | O38: 1443 | P38: 1479 | Q38: 1690 | R38: 995 | S38: 1374 | T38: 1134 | BB38: =SUM(B38:BA38) -> 24386 | BC38: =BB38-(SUMIF(B38:BA38,"<>0",B103:BA103)) -> 3060
A39: 北部湾 | B39: 2211 | C39: 1969 | D39: 2109 | E39: 2356 | F39: 1934 | G39: 2020 | H39: 1953 | I39: 1402 | J39: 1071 | K39: 2409 | L39: 2299 | M39: 2356 | N39: 2241 | O39: 2519 | P39: 1942 | Q39: 2566 | R39: 2168 | S39: 1971 | T39: 1550 | BB39: =SUM(B39:BA39) -> 39046 | BC39: =BB39-(SUMIF(B39:BA39,"<>0",B104:BA104)) -> 10062
A40: 南岗分公司 | B40: 801 | C40: 392 | D40: 607 | E40: 687 | F40: 809 | G40: 756 | H40: 869 | I40: 122 | J40: 74 | K40: 666 | L40: 511 | M40: 623 | N40: 609 | O40: 1161 | P40: 273 | Q40: 353 | R40: 1196 | S40: 668 | T40: 190 | BB40: =SUM(B40:BA40) -> 11367 | BC40: =BB40-(SUMIF(B40:BA40,"<>0",B105:BA105)) -> 4307
A41: 自营总计 | B41: 11086 | C41: 9069 | D41: 10865 | E41: 10307 | F41: 10367 | G41: 9628 | H41: 9211 | I41: 3086 | J41: 2270 | K41: 8190 | L41: 10484 | M41: 10403 | N41: 10840 | O41: 11449 | P41: 9395 | Q41: 10900 | R41: 10352 | S41: 10170 | T41: 6828 | BB41: =SUM(B41:BA41) -> 174900 | BC41: =BB41-(SUMIF(B41:BA41,"<>0",B106:BA106)) -> 2322
A42: 总计完成 | B42: 20047 | C42: 16564 | D42: 20018 | E42: 19403 | F42: 19359 | G42: 18426 | H42: 18477 | I42: 6811 | J42: 4314 | K42: 15456 | L42: 20707 | M42: 20498 | N42: 20432 | O42: 21478 | P42: 17627 | Q42: 20939 | R42: 20105 | S42: 19547 | T42: 13577 | BB42: =SUM(B42:BA42) -> 333785 | BC42: =BB42-(SUMIF(B42:BA42,"<>0",B107:BA107)) -> 48141 | BD42: 箱量增长
BD43: 产值增长
A44: 自营每周产值（2026年） | B44: 第1周 | C44: 第2周 | D44: 第3周 | E44: 第4周 | F44: 第5周 | G44: 第6周 | H44: 第7周 | I44: 第8周 | J44: 第9周 | K44: 第10周 | L44: 第11周 | M44: 第12周 | N44: 第13周 | O44: 第14周 | P44: 第15周 | Q44: 第16周 | R44: 第17周 | S44: 第18周 | T44: 第19周 | U44: 第20周 | V44: 第21周 | W44: 第22周 | X44: 第23周 | Y44: 第24周 | Z44: 第25周 | AA44: 第26周 | AB44: 第27周 | AC44: 第28周 | AD44: 第29周 | AE44: 第30周 | AF44: 第31周 | AG44: 第32周 | AH44: 第33周 | AI44: 第34周 | AJ44: 第35周 | AK44: 第36周 | AL44: 第37周 | AM44: 第38周 | AN44: 第39周 | AO44: 第40周 | AP44: 第41周 | AQ44: 第42周 | AR44: 第43周 | AS44: 第44周 | AT44: 第45周 | AU44: 第46周 | AV44: 第47周 | AW44: 第48周 | AX44: 第49周 | AY44: 第50周 | AZ44: 第51周 | BA44: 第52周 | BB44: 合计 | BC44: 同比2025年
A45: 深圳运营中心 | B45: 257454.83 | C45: 494272.15 | D45: 1054131.3 | E45: 1107480.2 | F45: 1327075.5 | G45: 421899.87 | H45: 331043.96 | I45: 16986.34 | J45: 131134.75 | K45: 243342.46 | L45: 242144.27 | M45: 345035.92 | N45: 323318.89 | O45: 662295.68 | P45: 751614.5 | Q45: 1142097.7 | R45: 1892854.1 | S45: 1388119.4 | T45: 216721.8 | BB45: =SUM(B45:BA45) -> 12349024 | BC45: =BB45-(SUMIF(B45:BA45,"<>0",B110:BA110)) -> 4839676
A46: 广州运营中心 | B46: 850408.98 | C46: 569018.76 | D46: 833531.29 | E46: 677114.84 | F46: 761824.89 | G46: 670480.99 | H46: 600611.47 | I46: 177803.02 | J46: 94957.43 | K46: 509760.05 | L46: 717742.63 | M46: 780496.58 | N46: 638699.17 | O46: 722678.24 | P46: 713124.51 | Q46: 687279.49 | R46: 783153.69 | S46: 677523.56 | T46: 469814.53 | BB46: =SUM(B46:BA46) -> 11936024 | BC46: =BB46-(SUMIF(B46:BA46,"<>0",B111:BA111)) -> -922861
